Workbook
Name teams: [1]Prices!$B$3:$I$34

Sheet Include
A1: EntryName | B1: Email
A2: Corey Strand | B2: corey.j.strand@gmail.com
A3: Corey Strand V2 | B3: corey.j.strand@gmail.com
A4: petelochner1 | B4: Peter.Lochner@ampf.com
A5: MatthewSchaefer | B5: mschaefer0825@gmail.com
A6: Marissa Cleaveland2 | B6: Marissa.Cleaveland@nimblelytic.com
A7: John Falck | B7: John@contractcaulking.com
A8: Manson1ColumbusGotLost | B8: paul@claireandpaul.net
A9: Manson2SudAmericaDrama | B9: paul@claireandpaul.net
A10: Manson3HeartofHearts | B10: paul@claireandpaul.net
A11: NickHanson1 | B11: Nicholas.Hanson@ampf.com
A12: NickHanson2 | B12: Nicholas.Hanson@ampf.com
... A101: Andy F2 | B101: dignund@yahoo.com

Sheet PickList
A1: Entry | B1: Attribute | C1: Value | D1: PickTyoe
A2: Corey Strand | B2: Team 1 | C2: Germany | D2: long
A3: Corey Strand | B3: Team 2 | C3: Norway | D3: long
A4: Corey Strand | B4: Team 3 | C4: Netherlands | D4: long
A5: Corey Strand | B5: Team 4 | C5: Japan | D5: long
A6: Corey Strand | B6: Team 5 | C6: Mexico | D6: long
A7: Corey Strand | B7: Team 6 | C7: Qatar | D7: long
A8: Corey Strand | B8: Short | C8: England | D8: short
A9: Corey Strand V2 | B9: Team 1 | C9: England | D9: long
A10: Corey Strand V2 | B10: Team 2 | C10: Spain | D10: long
A11: Corey Strand V2 | B11: Team 3 | C11: Algeria | D11: long
A12: Corey Strand V2 | B12: Short | C12: Belgium | D12: short
... A649: Andy F2 | B649: Short | C649: Portugal | D649: short

Sheet Entries
B1: Entry | C1: Team 1 | D1: Team 2 | E1: Team 3 | F1: Team 4 | G1: Team 5 | H1: Team 6 | I1: Team 7 | J1: Team 8 | K1: Team 9 | L1: Short | N1: 1 | O1: 2 | P1: 3 | Q1: 4 | R1: 5 | S1: 6 | T1: 7 | U1: 8 | V1: 9 | W1: S
B2: Corey Strand | C2: Germany | D2: Norway | E2: Netherlands | F2: Japan | G2: Mexico | H2: Qatar | L2: England | N2: =IFERROR(HLOOKUP(C2,Standings!$F$3:$BA$5,3,FALSE),0) -> 45 | O2: =IFERROR(HLOOKUP(D2,Standings!$F$3:$BA$5,3,FALSE),0) -> 30 | P2: =IFERROR(HLOOKUP(E2,Standings!$F$3:$BA$5,3,FALSE),0) -> 35 | Q2: =IFERROR(HLOOKUP(F2,Standings!$F$3:$BA$5,3,FALSE),0) -> 20 | R2: =IFERROR(HLOOKUP(G2,Standings!$F$3:$BA$5,3,FALSE),0) -> 27 | S2: =IFERROR(HLOOKUP(H2,Standings!$F$3:$BA$5,3,FALSE),0) -> 3 | T2: =IFERROR(HLOOKUP(I2,Standings!$F$3:$BA$5,3,FALSE),0) -> 0 | U2: =IFERROR(HLOOKUP(J2,Standings!$F$3:$BA$5,3,FALSE),0) -> 0 | V2: =IFERROR(HLOOKUP(K2,Standings!$F$3:$BA$5,3,FALSE),0) -> 0 | W2: =-IFERROR(HLOOKUP(L2,Standings!$F$3:$BA$5,3,FALSE),0) -> -60 | X2: =SUM(N2:W2) -> 100
B3: Corey Strand V2 | C3: England | D3: Spain | E3: Algeria | L3: Belgium | N3: =IFERROR(HLOOKUP(C3,Standings!$F$3:$BA$5,3,FALSE),0) -> 60 | O3: =IFERROR(HLOOKUP(D3,Standings!$F$3:$BA$5,3,FALSE),0) -> 70 | P3: =IFERROR(HLOOKUP(E3,Standings!$F$3:$BA$5,3,FALSE),0) -> 8 | Q3: =IFERROR(HLOOKUP(F3,Standings!$F$3:$BA$5,3,FALSE),0) -> 0 | R3: =IFERROR(HLOOKUP(G3,Standings!$F$3:$BA$5,3,FALSE),0) -> 0 | S3: =IFERROR(HLOOKUP(H3,Standings!$F$3:$BA$5,3,FALSE),0) -> 0 | T3: =IFERROR(HLOOKUP(I3,Standings!$F$3:$BA$5,3,FALSE),0) -> 0 | U3: =IFERROR(HLOOKUP(J3,Standings!$F$3:$BA$5,3,FALSE),0) -> 0 | V3: =IFERROR(HLOOKUP(K3,Standings!$F$3:$BA$5,3,FALSE),0) -> 0 | W3: =-IFERROR(HLOOKUP(L3,Standings!$F$3:$BA$5,3,FALSE),0) -> -38 | X3: =SUM(N3:W3) -> 100
B4: petelochner1 | C4: Spain | D4: Austria | E4: Croatia | F4: Belgium | G4: USA | L4: England | N4: =IFERROR(HLOOKUP(C4,Standings!$F$3:$BA$5,3,FALSE),0) -> 70 | O4: =IFERROR(HLOOKUP(D4,Standings!$F$3:$BA$5,3,FALSE),0) -> 12 | P4: =IFERROR(HLOOKUP(E4,Standings!$F$3:$BA$5,3,FALSE),0) -> 16 | Q4: =IFERROR(HLOOKUP(F4,Standings!$F$3:$BA$5,3,FALSE),0) -> 38 | R4: =IFERROR(HLOOKUP(G4,Standings!$F$3:$BA$5,3,FALSE),0) -> 23 | S4: =IFERROR(HLOOKUP(H4,Standings!$F$3:$BA$5,3,FALSE),0) -> 0 | T4: =IFERROR(HLOOKUP(I4,Standings!$F$3:$BA$5,3,FALSE),0) -> 0 | U4: =IFERROR(HLOOKUP(J4,Standings!$F$3:$BA$5,3,FALSE),0) -> 0 | V4: =IFERROR(HLOOKUP(K4,Standings!$F$3:$BA$5,3,FALSE),0) -> 0 | W4: =-IFERROR(HLOOKUP(L4,Standings!$F$3:$BA$5,3,FALSE),0) -> -60 | X4: =SUM(N4:W4) -> 99
B5: MatthewSchaefer | C5: Argentina | D5: Spain | E5: Norway | L5: Brazil | N5: =IFERROR(HLOOKUP(C5,Standings!$F$3:$BA$5,3,FALSE),0) -> 52 | O5: =IFERROR(HLOOKUP(D5,Standings!$F$3:$BA$5,3,FALSE),0) -> 70 | P5: =IFERROR(HLOOKUP(E5,Standings!$F$3:$BA$5,3,FALSE),0) -> 30 | Q5: =IFERROR(HLOOKUP(F5,Standings!$F$3:$BA$5,3,FALSE),0) -> 0 | R5: =IFERROR(HLOOKUP(G5,Standings!$F$3:$BA$5,3,FALSE),0) -> 0 | S5: =IFERROR(HLOOKUP(H5,Standings!$F$3:$BA$5,3,FALSE),0) -> 0 | T5: =IFERROR(HLOOKUP(I5,Standings!$F$3:$BA$5,3,FALSE),0) -> 0 | U5: =IFERROR(HLOOKUP(J5,Standings!$F$3:$BA$5,3,FALSE),0) -> 0 | V5: =IFERROR(HLOOKUP(K5,Standings!$F$3:$BA$5,3,FALSE),0) -> 0 | W5: =-IFERROR(HLOOKUP(L5,Standings!$F$3:$BA$5,3,FALSE),0) -> -54 | X5: =SUM(N5:W5) -> 98
B6: Marissa Cleaveland2 | C6: Netherlands | D6: Türkiye | E6: Croatia | F6: Ecuador | G6: Czechia | N6: =IFERROR(HLOOKUP(C6,Standings!$F$3:$BA$5,3,FALSE),0) -> 35 | O6: =IFERROR(HLOOKUP(D6,Standings!$F$3:$BA$5,3,FALSE),0) -> 20 | P6: =IFERROR(HLOOKUP(E6,Standings!$F$3:$BA$5,3,FALSE),0) -> 16 | Q6: =IFERROR(HLOOKUP(F6,Standings!$F$3:$BA$5,3,FALSE),0) -> 17 | R6: =IFERROR(HLOOKUP(G6,Standings!$F$3:$BA$5,3,FALSE),0) -> 12 | S6: =IFERROR(HLOOKUP(H6,Standings!$F$3:$BA$5,3,FALSE),0) -> 0 | T6: =IFERROR(HLOOKUP(I6,Standings!$F$3:$BA$5,3,FALSE),0) -> 0 | U6: =IFERROR(HLOOKUP(J6,Standings!$F$3:$BA$5,3,FALSE),0) -> 0 | V6: =IFERROR(HLOOKUP(K6,Standings!$F$3:$BA$5,3,FALSE),0) -> 0 | W6: =-IFERROR(HLOOKUP(L6,Standings!$F$3:$BA$5,3,FALSE),0) -> 0 | X6: =SUM(N6:W6) -> 100
B7: John Falck | C7: Jordan | D7: England | E7: Qatar | F7: Sweden | G7: New Zealand | H7: France | L7: Argentina | N7: =IFERROR(HLOOKUP(C7,Standings!$F$3:$BA$5,3,FALSE),0) -> 3 | O7: =IFERROR(HLOOKUP(D7,Standings!$F$3:$BA$5,3,FALSE),0) -> 60 | P7: =IFERROR(HLOOKUP(E7,Standings!$F$3:$BA$5,3,FALSE),0) -> 3 | Q7: =IFERROR(HLOOKUP(F7,Standings!$F$3:$BA$5,3,FALSE),0) -> 14 | R7: =IFERROR(HLOOKUP(G7,Standings!$F$3:$BA$5,3,FALSE),0) -> 4 | S7: =IFERROR(HLOOKUP(H7,Standings!$F$3:$BA$5,3,FALSE),0) -> 68 | T7: =IFERROR(HLOOKUP(I7,Standings!$F$3:$BA$5,3,FALSE),0) -> 0 | U7: =IFERROR(HLOOKUP(J7,Standings!$F$3:$BA$5,3,FALSE),0) -> 0 | V7: =IFERROR(HLOOKUP(K7,Standings!$F$3:$BA$5,3,FALSE),0) -> 0 | W7: =-IFERROR(HLOOKUP(L7,Standings!$F$3:$BA$5,3,FALSE),0) -> -52 | X7: =SUM(N7:W7) -> 100
B8: Manson1ColumbusGotLost | C8: France | D8: Germany | E8: Mexico | F8: Switzerland | L8: Spain | N8: =IFERROR(HLOOKUP(C8,Standings!$F$3:$BA$5,3,FALSE),0) -> 68 | O8: =IFERROR(HLOOKUP(D8,Standings!$F$3:$BA$5,3,FALSE),0) -> 45 | P8: =IFERROR(HLOOKUP(E8,Standings!$F$3:$BA$5,3,FALSE),0) -> 27 | Q8: =IFERROR(HLOOKUP(F8,Standings!$F$3:$BA$5,3,FALSE),0) -> 26 | R8: =IFERROR(HLOOKUP(G8,Standings!$F$3:$BA$5,3,FALSE),0) -> 0 | S8: =IFERROR(HLOOKUP(H8,Standings!$F$3:$BA$5,3,FALSE),0) -> 0 | T8: =IFERROR(HLOOKUP(I8,Standings!$F$3:$BA$5,3,FALSE),0) -> 0 | U8: =IFERROR(HLOOKUP(J8,Standings!$F$3:$BA$5,3,FALSE),0) -> 0 | V8: =IFERROR(HLOOKUP(K8,Standings!$F$3:$BA$5,3,FALSE),0) -> 0 | W8: =-IFERROR(HLOOKUP(L8,Standings!$F$3:$BA$5,3,FALSE),0) -> -70 | X8: =SUM(N8:W8) -> 96
B9: Manson2SudAmericaDrama | C9: Argentina | D9: Portugal | E9: Japan | F9: Morocco | G9: Haiti | H9: Panama | L9: Brazil | N9: =IFERROR(HLOOKUP(C9,Standings!$F$3:$BA$5,3,FALSE),0) -> 52 | O9: =IFERROR(HLOOKUP(D9,Standings!$F$3:$BA$5,3,FALSE),0) -> 50 | P9: =IFERROR(HLOOKUP(E9,Standings!$F$3:$BA$5,3,FALSE),0) -> 20 | Q9: =IFERROR(HLOOKUP(F9,Standings!$F$3:$BA$5,3,FALSE),0) -> 21 | R9: =IFERROR(HLOOKUP(G9,Standings!$F$3:$BA$5,3,FALSE),0) -> 5 | S9: =IFERROR(HLOOKUP(H9,Standings!$F$3:$BA$5,3,FALSE),0) -> 5 | T9: =IFERROR(HLOOKUP(I9,Standings!$F$3:$BA$5,3,FALSE),0) -> 0 | U9: =IFERROR(HLOOKUP(J9,Standings!$F$3:$BA$5,3,FALSE),0) -> 0 | V9: =IFERROR(HLOOKUP(K9,Standings!$F$3:$BA$5,3,FALSE),0) -> 0 | W9: =-IFERROR(HLOOKUP(L9,Standings!$F$3:$BA$5,3,FALSE),0) -> -54 | X9: =SUM(N9:W9) -> 99
B10: Manson3HeartofHearts | C10: France | D10: USA | E10: Japan | F10: Croatia | G10: Czechia | H10: Senegal | I10: Ghana | L10: England | N10: =IFERROR(HLOOKUP(C10,Standings!$F$3:$BA$5,3,FALSE),0) -> 68 | O10: =IFERROR(HLOOKUP(D10,Standings!$F$3:$BA$5,3,FALSE),0) -> 23 | P10: =IFERROR(HLOOKUP(E10,Standings!$F$3:$BA$5,3,FALSE),0) -> 20 | Q10: =IFERROR(HLOOKUP(F10,Standings!$F$3:$BA$5,3,FALSE),0) -> 16 | R10: =IFERROR(HLOOKUP(G10,Standings!$F$3:$BA$5,3,FALSE),0) -> 12 | S10: =IFERROR(HLOOKUP(H10,Standings!$F$3:$BA$5,3,FALSE),0) -> 13 | T10: =IFERROR(HLOOKUP(I10,Standings!$F$3:$BA$5,3,FALSE),0) -> 7 | U10: =IFERROR(HLOOKUP(J10,Standings!$F$3:$BA$5,3,FALSE),0) -> 0 | V10: =IFERROR(HLOOKUP(K10,Standings!$F$3:$BA$5,3,FALSE),0) -> 0 | W10: =-IFERROR(HLOOKUP(L10,Standings!$F$3:$BA$5,3,FALSE),0) -> -60 | X10: =SUM(N10:W10) -> 99
B11: NickHanson1 | C11: Argentina | D11: Mexico | E11: Türkiye | F11: Canada | G11: Uruguay | H11: Ecuador | I11: Scotland | J11: Panama | K11: Jordan | L11: Spain | N11: =IFERROR(HLOOKUP(C11,Standings!$F$3:$BA$5,3,FALSE),0) -> 52 | O11: =IFERROR(HLOOKUP(D11,Standings!$F$3:$BA$5,3,FALSE),0) -> 27 | P11: =IFERROR(HLOOKUP(E11,Standings!$F$3:$BA$5,3,FALSE),0) -> 20 | Q11: =IFERROR(HLOOKUP(F11,Standings!$F$3:$BA$5,3,FALSE),0) -> 19 | R11: =IFERROR(HLOOKUP(G11,Standings!$F$3:$BA$5,3,FALSE),0) -> 18 | S11: =IFERROR(HLOOKUP(H11,Standings!$F$3:$BA$5,3,FALSE),0) -> 17 | T11: =IFERROR(HLOOKUP(I11,Standings!$F$3:$BA$5,3,FALSE),0) -> 9 | U11: =IFERROR(HLOOKUP(J11,Standings!$F$3:$BA$5,3,FALSE),0) -> 5 | V11: =IFERROR(HLOOKUP(K11,Standings!$F$3:$BA$5,3,FALSE),0) -> 3 | W11: =-IFERROR(HLOOKUP(L11,Standings!$F$3:$BA$5,3,FALSE),0) -> -70 | X11: =SUM(N11:W11) -> 100
B12: NickHanson2 | C12: Brazil | D12: Germany | E12: Mexico | F12: Ecuador | G12: Algeria | H12: Australia | I12: Egypt | L12: France | N12: =IFERROR(HLOOKUP(C12,Standings!$F$3:$BA$5,3,FALSE),0) -> 54 | O12: =IFERROR(HLOOKUP(D12,Standings!$F$3:$BA$5,3,FALSE),0) -> 45 | P12: =IFERROR(HLOOKUP(E12,Standings!$F$3:$BA$5,3,FALSE),0) -> 27 | Q12: =IFERROR(HLOOKUP(F12,Standings!$F$3:$BA$5,3,FALSE),0) -> 17 | R12: =IFERROR(HLOOKUP(G12,Standings!$F$3:$BA$5,3,FALSE),0) -> 8 | S12: =IFERROR(HLOOKUP(H12,Standings!$F$3:$BA$5,3,FALSE),0) -> 7 | T12: =IFERROR(HLOOKUP(I12,Standings!$F$3:$BA$5,3,FALSE),0) -> 10 | U12: =IFERROR(HLOOKUP(J12,Standings!$F$3:$BA$5,3,FALSE),0) -> 0 | V12: =IFERROR(HLOOKUP(K12,Standings!$F$3:$BA$5,3,FALSE),0) -> 0 | W12: =-IFERROR(HLOOKUP(L12,Standings!$F$3:$BA$5,3,FALSE),0) -> -68 | X12: =SUM(N12:W12) -> 100
B13: shoup1 | C13: USA | D13: Canada | E13: Colombia | F13: Sweden | G13: Morocco | H13: Ecuador | I13: Croatia | L13: Netherlands | N13: =IFERROR(HLOOKUP(C13,Standings!$F$3:$BA$5,3,FALSE),0) -> 23 | O13: =IFERROR(HLOOKUP(D13,Standings!$F$3:$BA$5,3,FALSE),0) -> 19 | P13: =IFERROR(HLOOKUP(E13,Standings!$F$3:$BA$5,3,FALSE),0) -> 25 | Q13: =IFERROR(HLOOKUP(F13,Standings!$F$3:$BA$5,3,FALSE),0) -> 14 | R13: =IFERROR(HLOOKUP(G13,Standings!$F$3:$BA$5,3,FALSE),0) -> 21 | S13: =IFERROR(HLOOKUP(H13,Standings!$F$3:$BA$5,3,FALSE),0) -> 17 | T13: =IFERROR(HLOOKUP(I13,Standings!$F$3:$BA$5,3,FALSE),0) -> 16 | U13: =IFERROR(HLOOKUP(J13,Standings!$F$3:$BA$5,3,FALSE),0) -> 0 | V13: =IFERROR(HLOOKUP(K13,Standings!$F$3:$BA$5,3,FALSE),0) -> 0 | W13: =-IFERROR(HLOOKUP(L13,Standings!$F$3:$BA$5,3,FALSE),0) -> -35 | X13: =SUM(N13:W13) -> 100
B14: shoup2 | C14: Germany | D14: Türkiye | E14: Switzerland | F14: Belgium | L14: Norway | N14: =IFERROR(HLOOKUP(C14,Standings!$F$3:$BA$5,3,FALSE),0) -> 45 | O14: =IFERROR(HLOOKUP(D14,Standings!$F$3:$BA$5,3,FALSE),0) -> 20 | P14: =IFERROR(HLOOKUP(E14,Standings!$F$3:$BA$5,3,FALSE),0) -> 26 | Q14: =IFERROR(HLOOKUP(F14,Standings!$F$3:$BA$5,3,FALSE),0) -> 38 | R14: =IFERROR(HLOOKUP(G14,Standings!$F$3:$BA$5,3,FALSE),0) -> 0 | S14: =IFERROR(HLOOKUP(H14,Standings!$F$3:$BA$5,3,FALSE),0) -> 0 | T14: =IFERROR(HLOOKUP(I14,Standings!$F$3:$BA$5,3,FALSE),0) -> 0 | U14: =IFERROR(HLOOKUP(J14,Standings!$F$3:$BA$5,3,FALSE),0) -> 0 | V14: =IFERROR(HLOOKUP(K14,Standings!$F$3:$BA$5,3,FALSE),0) -> 0 | W14: =-IFERROR(HLOOKUP(L14,Standings!$F$3:$BA$5,3,FALSE),0) -> -30 | X14: =SUM(N14:W14) -> 99
B15: AbbieSchaeferWorldCupPicks | C15: France | D15: Germany | E15: Belgium | L15: Argentina | N15: =IFERROR(HLOOKUP(C15,Standings!$F$3:$BA$5,3,FALSE),0) -> 68 | O15: =IFERROR(HLOOKUP(D15,Standings!$F$3:$BA$5,3,FALSE),0) -> 45 | P15: =IFERROR(HLOOKUP(E15,Standings!$F$3:$BA$5,3,FALSE),0) -> 38 | Q15: =IFERROR(HLOOKUP(F15,Standings!$F$3:$BA$5,3,FALSE),0) -> 0 | R15: =IFERROR(HLOOKUP(G15,Standings!$F$3:$BA$5,3,FALSE),0) -> 0 | S15: =IFERROR(HLOOKUP(H15,Standings!$F$3:$BA$5,3,FALSE),0) -> 0 | T15: =IFERROR(HLOOKUP(I15,Standings!$F$3:$BA$5,3,FALSE),0) -> 0 | U15: =IFERROR(HLOOKUP(J15,Standings!$F$3:$BA$5,3,FALSE),0) -> 0 | V15: =IFERROR(HLOOKUP(K15,Standings!$F$3:$BA$5,3,FALSE),0) -> 0 | W15: =-IFERROR(HLOOKUP(L15,Standings!$F$3:$BA$5,3,FALSE),0) -> -52 | X15: =SUM(N15:W15) -> 99
B16: JoelsBalance | C16: Portugal | D16: Mexico | E16: Switzerland | F16: Egypt | G16: Senegal | H16: Australia | I16: Tunisia | J16: Panama | L16: Germany | N16: =IFERROR(HLOOKUP(C16,Standings!$F$3:$BA$5,3,FALSE),0) -> 50 | O16: =IFERROR(HLOOKUP(D16,Standings!$F$3:$BA$5,3,FALSE),0) -> 27 | P16: =IFERROR(HLOOKUP(E16,Standings!$F$3:$BA$5,3,FALSE),0) -> 26 | Q16: =IFERROR(HLOOKUP(F16,Standings!$F$3:$BA$5,3,FALSE),0) -> 10 | R16: =IFERROR(HLOOKUP(G16,Standings!$F$3:$BA$5,3,FALSE),0) -> 13 | S16: =IFERROR(HLOOKUP(H16,Standings!$F$3:$BA$5,3,FALSE),0) -> 7 | T16: =IFERROR(HLOOKUP(I16,Standings!$F$3:$BA$5,3,FALSE),0) -> 7 | U16: =IFERROR(HLOOKUP(J16,Standings!$F$3:$BA$5,3,FALSE),0) -> 5 | V16: =IFERROR(HLOOKUP(K16,Standings!$F$3:$BA$5,3,FALSE),0) -> 0 | W16: =-IFERROR(HLOOKUP(L16,Standings!$F$3:$BA$5,3,FALSE),0) -> -45 | X16: =SUM(N16:W16) -> 100
B17: JoelsBigShort | C17: Netherlands | D17: Switzerland | E17: Mexico | F17: Japan | G17: Canada | H17: Croatia | I17: Austria | J17: Egypt | K17: Curaçao | L17: France | N17: =IFERROR(HLOOKUP(C17,Standings!$F$3:$BA$5,3,FALSE),0) -> 35 | O17: =IFERROR(HLOOKUP(D17,Standings!$F$3:$BA$5,3,FALSE),0) -> 26 | P17: =IFERROR(HLOOKUP(E17,Standings!$F$3:$BA$5,3,FALSE),0) -> 27 | Q17: =IFERROR(HLOOKUP(F17,Standings!$F$3:$BA$5,3,FALSE),0) -> 20 | R17: =IFERROR(HLOOKUP(G17,Standings!$F$3:$BA$5,3,FALSE),0) -> 19 | S17: =IFERROR(HLOOKUP(H17,Standings!$F$3:$BA$5,3,FALSE),0) -> 16 | T17: =IFERROR(HLOOKUP(I17,Standings!$F$3:$BA$5,3,FALSE),0) -> 12 | U17: =IFERROR(HLOOKUP(J17,Standings!$F$3:$BA$5,3,FALSE),0) -> 10 | V17: =IFERROR(HLOOKUP(K17,Standings!$F$3:$BA$5,3,FALSE),0) -> 3 | W17: =-IFERROR(HLOOKUP(L17,Standings!$F$3:$BA$5,3,FALSE),0) -> -68 | X17: =SUM(N17:W17) -> 100
B18: JoelsSenegalFlex | C18: Netherlands | D18: Switzerland | E18: Mexico | F18: Japan | G18: Canada | H18: Croatia | I18: Senegal | J18: Egypt | K18: Curaçao | L18: Spain | N18: =IFERROR(HLOOKUP(C18,Standings!$F$3:$BA$5,3,FALSE),0) -> 35 | O18: =IFERROR(HLOOKUP(D18,Standings!$F$3:$BA$5,3,FALSE),0) -> 26 | P18: =IFERROR(HLOOKUP(E18,Standings!$F$3:$BA$5,3,FALSE),0) -> 27 | Q18: =IFERROR(HLOOKUP(F18,Standings!$F$3:$BA$5,3,FALSE),0) -> 20 | R18: =IFERROR(HLOOKUP(G18,Standings!$F$3:$BA$5,3,FALSE),0) -> 19 | S18: =IFERROR(HLOOKUP(H18,Standings!$F$3:$BA$5,3,FALSE),0) -> 16 | T18: =IFERROR(HLOOKUP(I18,Standings!$F$3:$BA$5,3,FALSE),0) -> 13 | U18: =IFERROR(HLOOKUP(J18,Standings!$F$3:$BA$5,3,FALSE),0) -> 10 | V18: =IFERROR(HLOOKUP(K18,Standings!$F$3:$BA$5,3,FALSE),0) -> 3 | W18: =-IFERROR(HLOOKUP(L18,Standings!$F$3:$BA$5,3,FALSE),0) -> -70 | X18: =SUM(N18:W18) -> 99
B19: LaurenBullock | C19: France | D19: USA | E19: Scotland | F19: Egypt | G19: Ivory Coast | L19: Japan | N19: =IFERROR(HLOOKUP(C19,Standings!$F$3:$BA$5,3,FALSE),0) -> 68 | O19: =IFERROR(HLOOKUP(D19,Standings!$F$3:$BA$5,3,FALSE),0) -> 23 | P19: =IFERROR(HLOOKUP(E19,Standings!$F$3:$BA$5,3,FALSE),0) -> 9 | Q19: =IFERROR(HLOOKUP(F19,Standings!$F$3:$BA$5,3,FALSE),0) -> 10 | R19: =IFERROR(HLOOKUP(G19,Standings!$F$3:$BA$5,3,FALSE),0) -> 9 | S19: =IFERROR(HLOOKUP(H19,Standings!$F$3:$BA$5,3,FALSE),0) -> 0 | T19: =IFERROR(HLOOKUP(I19,Standings!$F$3:$BA$5,3,FALSE),0) -> 0 | U19: =IFERROR(HLOOKUP(J19,Standings!$F$3:$BA$5,3,FALSE),0) -> 0 | V19: =IFERROR(HLOOKUP(K19,Standings!$F$3:$BA$5,3,FALSE),0) -> 0 | W19: =-IFERROR(HLOOKUP(L19,Standings!$F$3:$BA$5,3,FALSE),0) -> -20 | X19: =SUM(N19:W19) -> 99
B20: WillBullock | C20: Canada | D20: Czechia | E20: Senegal | F20: Japan | G20: Australia | H20: Iran | I20: Egypt | J20: Ecuador | K20: Croatia | L20: USA | N20: =IFERROR(HLOOKUP(C20,Standings!$F$3:$BA$5,3,FALSE),0) -> 19 | O20: =IFERROR(HLOOKUP(D20,Standings!$F$3:$BA$5,3,FALSE),0) -> 12 | P20: =IFERROR(HLOOKUP(E20,Standings!$F$3:$BA$5,3,FALSE),0) -> 13 | Q20: =IFERROR(HLOOKUP(F20,Standings!$F$3:$BA$5,3,FALSE),0) -> 20 | R20: =IFERROR(HLOOKUP(G20,Standings!$F$3:$BA$5,3,FALSE),0) -> 7 | S20: =IFERROR(HLOOKUP(H20,Standings!$F$3:$BA$5,3,FALSE),0) -> 8 | T20: =IFERROR(HLOOKUP(I20,Standings!$F$3:$BA$5,3,FALSE),0) -> 10 | U20: =IFERROR(HLOOKUP(J20,Standings!$F$3:$BA$5,3,FALSE),0) -> 17 | V20: =IFERROR(HLOOKUP(K20,Standings!$F$3:$BA$5,3,FALSE),0) -> 16 | W20: =-IFERROR(HLOOKUP(L20,Standings!$F$3:$BA$5,3,FALSE),0) -> -23 | X20: =SUM(N20:W20) -> 99
B21: JohnBullock1 | C21: Japan | D21: France | E21: USA | F21: Morocco | G21: Qatar | L21: Netherlands | N21: =IFERROR(HLOOKUP(C21,Standings!$F$3:$BA$5,3,FALSE),0) -> 20 | O21: =IFERROR(HLOOKUP(D21,Standings!$F$3:$BA$5,3,FALSE),0) -> 68 | P21: =IFERROR(HLOOKUP(E21,Standings!$F$3:$BA$5,3,FALSE),0) -> 23 | Q21: =IFERROR(HLOOKUP(F21,Standings!$F$3:$BA$5,3,FALSE),0) -> 21 | R21: =IFERROR(HLOOKUP(G21,Standings!$F$3:$BA$5,3,FALSE),0) -> 3 | S21: =IFERROR(HLOOKUP(H21,Standings!$F$3:$BA$5,3,FALSE),0) -> 0 | T21: =IFERROR(HLOOKUP(I21,Standings!$F$3:$BA$5,3,FALSE),0) -> 0 | U21: =IFERROR(HLOOKUP(J21,Standings!$F$3:$BA$5,3,FALSE),0) -> 0 | V21: =IFERROR(HLOOKUP(K21,Standings!$F$3:$BA$5,3,FALSE),0) -> 0 | W21: =-IFERROR(HLOOKUP(L21,Standings!$F$3:$BA$5,3,FALSE),0) -> -35 | X21: =SUM(N21:W21) -> 100
B22: JohnBullock2 | C22: England | D22: Colombia | E22: Uzbekistan | F22: Germany | G22: Scotland | H22: South Africa | L22: Portugal | N22: =IFERROR(HLOOKUP(C22,Standings!$F$3:$BA$5,3,FALSE),0) -> 60 | O22: =IFERROR(HLOOKUP(D22,Standings!$F$3:$BA$5,3,FALSE),0) -> 25 | P22: =IFERROR(HLOOKUP(E22,Standings!$F$3:$BA$5,3,FALSE),0) -> 5 | Q22: =IFERROR(HLOOKUP(F22,Standings!$F$3:$BA$5,3,FALSE),0) -> 45 | R22: =IFERROR(HLOOKUP(G22,Standings!$F$3:$BA$5,3,FALSE),0) -> 9 | S22: =IFERROR(HLOOKUP(H22,Standings!$F$3:$BA$5,3,FALSE),0) -> 6 | T22: =IFERROR(HLOOKUP(I22,Standings!$F$3:$BA$5,3,FALSE),0) -> 0 | U22: =IFERROR(HLOOKUP(J22,Standings!$F$3:$BA$5,3,FALSE),0) -> 0 | V22: =IFERROR(HLOOKUP(K22,Standings!$F$3:$BA$5,3,FALSE),0) -> 0 | W22: =-IFERROR(HLOOKUP(L22,Standings!$F$3:$BA$5,3,FALSE),0) -> -50 | X22: =SUM(N22:W22) -> 100
B23: AinsleyBullock | C23: USA | D23: Mexico | E23: Canada | F23: Ghana | G23: Algeria | H23: Japan | I23: Ecuador | J23: Saudi Arabia | L23: Switzerland | N23: =IFERROR(HLOOKUP(C23,Standings!$F$3:$BA$5,3,FALSE),0) -> 23 | O23: =IFERROR(HLOOKUP(D23,Standings!$F$3:$BA$5,3,FALSE),0) -> 27 | P23: =IFERROR(HLOOKUP(E23,Standings!$F$3:$BA$5,3,FALSE),0) -> 19 | Q23: =IFERROR(HLOOKUP(F23,Standings!$F$3:$BA$5,3,FALSE),0) -> 7 | R23: =IFERROR(HLOOKUP(G23,Standings!$F$3:$BA$5,3,FALSE),0) -> 8 | S23: =IFERROR(HLOOKUP(H23,Standings!$F$3:$BA$5,3,FALSE),0) -> 20 | T23: =IFERROR(HLOOKUP(I23,Standings!$F$3:$BA$5,3,FALSE),0) -> 17 | U23: =IFERROR(HLOOKUP(J23,Standings!$F$3:$BA$5,3,FALSE),0) -> 5 | V23: =IFERROR(HLOOKUP(K23,Standings!$F$3:$BA$5,3,FALSE),0) -> 0 | W23: =-IFERROR(HLOOKUP(L23,Standings!$F$3:$BA$5,3,FALSE),0) -> -26 | X23: =SUM(N23:W23) -> 100
B24: John Falck #2 | C24: Canada | D24: Norway | E24: Mexico | F24: England | G24: Japan | H24: Austria | L24: France | N24: =IFERROR(HLOOKUP(C24,Standings!$F$3:$BA$5,3,FALSE),0) -> 19 | O24: =IFERROR(HLOOKUP(D24,Standings!$F$3:$BA$5,3,FALSE),0) -> 30 | P24: =IFERROR(HLOOKUP(E24,Standings!$F$3:$BA$5,3,FALSE),0) -> 27 | Q24: =IFERROR(HLOOKUP(F24,Standings!$F$3:$BA$5,3,FALSE),0) -> 60 | R24: =IFERROR(HLOOKUP(G24,Standings!$F$3:$BA$5,3,FALSE),0) -> 20 | S24: =IFERROR(HLOOKUP(H24,Standings!$F$3:$BA$5,3,FALSE),0) -> 12 | T24: =IFERROR(HLOOKUP(I24,Standings!$F$3:$BA$5,3,FALSE),0) -> 0 | U24: =IFERROR(HLOOKUP(J24,Standings!$F$3:$BA$5,3,FALSE),0) -> 0 | V24: =IFERROR(HLOOKUP(K24,Standings!$F$3:$BA$5,3,FALSE),0) -> 0 | W24: =-IFERROR(HLOOKUP(L24,Standings!$F$3:$BA$5,3,FALSE),0) -> -68 | X24: =SUM(N24:W24) -> 100
B25: Tim Armbrustmacher1 | C25: Switzerland | D25: Ecuador | E25: Morocco | F25: Egypt | G25: Uruguay | H25: France | L25: England | N25: =IFERROR(HLOOKUP(C25,Standings!$F$3:$BA$5,3,FALSE),0) -> 26 | O25: =IFERROR(HLOOKUP(D25,Standings!$F$3:$BA$5,3,FALSE),0) -> 17 | P25: =IFERROR(HLOOKUP(E25,Standings!$F$3:$BA$5,3,FALSE),0) -> 21 | Q25: =IFERROR(HLOOKUP(F25,Standings!$F$3:$BA$5,3,FALSE),0) -> 10 | R25: =IFERROR(HLOOKUP(G25,Standings!$F$3:$BA$5,3,FALSE),0) -> 18 | S25: =IFERROR(HLOOKUP(H25,Standings!$F$3:$BA$5,3,FALSE),0) -> 68 | T25: =IFERROR(HLOOKUP(I25,Standings!$F$3:$BA$5,3,FALSE),0) -> 0 | U25: =IFERROR(HLOOKUP(J25,Standings!$F$3:$BA$5,3,FALSE),0) -> 0 | V25: =IFERROR(HLOOKUP(K25,Standings!$F$3:$BA$5,3,FALSE),0) -> 0 | W25: =-IFERROR(HLOOKUP(L25,Standings!$F$3:$BA$5,3,FALSE),0) -> -60 | X25: =SUM(N25:W25) -> 100
B26: Tim Armbrustmacher2 | C26: Mexico | D26: Senegal | E26: Qatar | F26: England | G26: Japan | L26: USA | N26: =IFERROR(HLOOKUP(C26,Standings!$F$3:$BA$5,3,FALSE),0) -> 27 | O26: =IFERROR(HLOOKUP(D26,Standings!$F$3:$BA$5,3,FALSE),0) -> 13 | P26: =IFERROR(HLOOKUP(E26,Standings!$F$3:$BA$5,3,FALSE),0) -> 3 | Q26: =IFERROR(HLOOKUP(F26,Standings!$F$3:$BA$5,3,FALSE),0) -> 60 | R26: =IFERROR(HLOOKUP(G26,Standings!$F$3:$BA$5,3,FALSE),0) -> 20 | S26: =IFERROR(HLOOKUP(H26,Standings!$F$3:$BA$5,3,FALSE),0) -> 0 | T26: =IFERROR(HLOOKUP(I26,Standings!$F$3:$BA$5,3,FALSE),0) -> 0 | U26: =IFERROR(HLOOKUP(J26,Standings!$F$3:$BA$5,3,FALSE),0) -> 0 | V26: =IFERROR(HLOOKUP(K26,Standings!$F$3:$BA$5,3,FALSE),0) -> 0 | W26: =-IFERROR(HLOOKUP(L26,Standings!$F$3:$BA$5,3,FALSE),0) -> -23 | X26: =SUM(N26:W26) -> 100
B27: MikePollei1 | C27: France | D27: Croatia | E27: Uruguay | F27: Austria | G27: Senegal | H27: Jordan | I27: Iran | L27: Belgium | N27: =IFERROR(HLOOKUP(C27,Standings!$F$3:$BA$5,3,FALSE),0) -> 68 | O27: =IFERROR(HLOOKUP(D27,Standings!$F$3:$BA$5,3,FALSE),0) -> 16 | P27: =IFERROR(HLOOKUP(E27,Standings!$F$3:$BA$5,3,FALSE),0) -> 18 | Q27: =IFERROR(HLOOKUP(F27,Standings!$F$3:$BA$5,3,FALSE),0) -> 12 | R27: =IFERROR(HLOOKUP(G27,Standings!$F$3:$BA$5,3,FALSE),0) -> 13 | S27: =IFERROR(HLOOKUP(H27,Standings!$F$3:$BA$5,3,FALSE),0) -> 3 | T27: =IFERROR(HLOOKUP(I27,Standings!$F$3:$BA$5,3,FALSE),0) -> 8 | U27: =IFERROR(HLOOKUP(J27,Standings!$F$3:$BA$5,3,FALSE),0) -> 0 | V27: =IFERROR(HLOOKUP(K27,Standings!$F$3:$BA$5,3,FALSE),0) -> 0 | W27: =-IFERROR(HLOOKUP(L27,Standings!$F$3:$BA$5,3,FALSE),0) -> -38 | X27: =SUM(N27:W27) -> 100
B28: MikePollei2 | C28: France | D28: Argentina | E28: Austria | F28: Curaçao | G28: Jordan | L28: Belgium | N28: =IFERROR(HLOOKUP(C28,Standings!$F$3:$BA$5,3,FALSE),0) -> 68 | O28: =IFERROR(HLOOKUP(D28,Standings!$F$3:$BA$5,3,FALSE),0) -> 52 | P28: =IFERROR(HLOOKUP(E28,Standings!$F$3:$BA$5,3,FALSE),0) -> 12 | Q28: =IFERROR(HLOOKUP(F28,Standings!$F$3:$BA$5,3,FALSE),0) -> 3 | R28: =IFERROR(HLOOKUP(G28,Standings!$F$3:$BA$5,3,FALSE),0) -> 3 | S28: =IFERROR(HLOOKUP(H28,Standings!$F$3:$BA$5,3,FALSE),0) -> 0 | T28: =IFERROR(HLOOKUP(I28,Standings!$F$3:$BA$5,3,FALSE),0) -> 0 | U28: =IFERROR(HLOOKUP(J28,Standings!$F$3:$BA$5,3,FALSE),0) -> 0 | V28: =IFERROR(HLOOKUP(K28,Standings!$F$3:$BA$5,3,FALSE),0) -> 0 | W28: =-IFERROR(HLOOKUP(L28,Standings!$F$3:$BA$5,3,FALSE),0) -> -38 | X28: =SUM(N28:W28) -> 100
B29: MichellePollei | C29: Argentina | D29: Uruguay | E29: Croatia | F29: Austria | G29: Senegal | H29: Jordan | I29: Curaçao | J29: Qatar | L29: Türkiye | N29: =IFERROR(HLOOKUP(C29,Standings!$F$3:$BA$5,3,FALSE),0) -> 52 | O29: =IFERROR(HLOOKUP(D29,Standings!$F$3:$BA$5,3,FALSE),0) -> 18 | P29: =IFERROR(HLOOKUP(E29,Standings!$F$3:$BA$5,3,FALSE),0) -> 16 | Q29: =IFERROR(HLOOKUP(F29,Standings!$F$3:$BA$5,3,FALSE),0) -> 12 | R29: =IFERROR(HLOOKUP(G29,Standings!$F$3:$BA$5,3,FALSE),0) -> 13 | S29: =IFERROR(HLOOKUP(H29,Standings!$F$3:$BA$5,3,FALSE),0) -> 3 | T29: =IFERROR(HLOOKUP(I29,Standings!$F$3:$BA$5,3,FALSE),0) -> 3 | U29: =IFERROR(HLOOKUP(J29,Standings!$F$3:$BA$5,3,FALSE),0) -> 3 | V29: =IFERROR(HLOOKUP(K29,Standings!$F$3:$BA$5,3,FALSE),0) -> 0 | W29: =-IFERROR(HLOOKUP(L29,Standings!$F$3:$BA$5,3,FALSE),0) -> -20 | X29: =SUM(N29:W29) -> 100
B30: SarahPollei | C30: Portugal | D30: Uruguay | E30: Croatia | F30: Austria | G30: Senegal | H30: Iran | I30: Jordan | L30: Türkiye | N30: =IFERROR(HLOOKUP(C30,Standings!$F$3:$BA$5,3,FALSE),0) -> 50 | O30: =IFERROR(HLOOKUP(D30,Standings!$F$3:$BA$5,3,FALSE),0) -> 18 | P30: =IFERROR(HLOOKUP(E30,Standings!$F$3:$BA$5,3,FALSE),0) -> 16 | Q30: =IFERROR(HLOOKUP(F30,Standings!$F$3:$BA$5,3,FALSE),0) -> 12 | R30: =IFERROR(HLOOKUP(G30,Standings!$F$3:$BA$5,3,FALSE),0) -> 13 | S30: =IFERROR(HLOOKUP(H30,Standings!$F$3:$BA$5,3,FALSE),0) -> 8 | T30: =IFERROR(HLOOKUP(I30,Standings!$F$3:$BA$5,3,FALSE),0) -> 3 | U30: =IFERROR(HLOOKUP(J30,Standings!$F$3:$BA$5,3,FALSE),0) -> 0 | V30: =IFERROR(HLOOKUP(K30,Standings!$F$3:$BA$5,3,FALSE),0) -> 0 | W30: =-IFERROR(HLOOKUP(L30,Standings!$F$3:$BA$5,3,FALSE),0) -> -20 | X30: =SUM(N30:W30) -> 100
B31: Sean ODonnell1 | C31: USA | D31: Switzerland | E31: South Korea | F31: Belgium | G31: Saudi Arabia | H31: Ecuador | I31: Scotland | J31: Ivory Coast | K31: Tunisia | L31: Germany | N31: =IFERROR(HLOOKUP(C31,Standings!$F$3:$BA$5,3,FALSE),0) -> 23 | O31: =IFERROR(HLOOKUP(D31,Standings!$F$3:$BA$5,3,FALSE),0) -> 26 | P31: =IFERROR(HLOOKUP(E31,Standings!$F$3:$BA$5,3,FALSE),0) -> 11 | Q31: =IFERROR(HLOOKUP(F31,Standings!$F$3:$BA$5,3,FALSE),0) -> 38 | R31: =IFERROR(HLOOKUP(G31,Standings!$F$3:$BA$5,3,FALSE),0) -> 5 | S31: =IFERROR(HLOOKUP(H31,Standings!$F$3:$BA$5,3,FALSE),0) -> 17 | T31: =IFERROR(HLOOKUP(I31,Standings!$F$3:$BA$5,3,FALSE),0) -> 9 | U31: =IFERROR(HLOOKUP(J31,Standings!$F$3:$BA$5,3,FALSE),0) -> 9 | V31: =IFERROR(HLOOKUP(K31,Standings!$F$3:$BA$5,3,FALSE),0) -> 7 | W31: =-IFERROR(HLOOKUP(L31,Standings!$F$3:$BA$5,3,FALSE),0) -> -45 | X31: =SUM(N31:W31) -> 100
B32: Sean ODonnell2 | C32: Netherlands | D32: Morocco | E32: USA | F32: Belgium | G32: Colombia | H32: Scotland | I32: Iran | J32: Tunisia | K32: Cape Verde | L32: Spain | N32: =IFERROR(HLOOKUP(C32,Standings!$F$3:$BA$5,3,FALSE),0) -> 35 | O32: =IFERROR(HLOOKUP(D32,Standings!$F$3:$BA$5,3,FALSE),0) -> 21 | P32: =IFERROR(HLOOKUP(E32,Standings!$F$3:$BA$5,3,FALSE),0) -> 23 | Q32: =IFERROR(HLOOKUP(F32,Standings!$F$3:$BA$5,3,FALSE),0) -> 38 | R32: =IFERROR(HLOOKUP(G32,Standings!$F$3:$BA$5,3,FALSE),0) -> 25 | S32: =IFERROR(HLOOKUP(H32,Standings!$F$3:$BA$5,3,FALSE),0) -> 9 | T32: =IFERROR(HLOOKUP(I32,Standings!$F$3:$BA$5,3,FALSE),0) -> 8 | U32: =IFERROR(HLOOKUP(J32,Standings!$F$3:$BA$5,3,FALSE),0) -> 7 | V32: =IFERROR(HLOOKUP(K32,Standings!$F$3:$BA$5,3,FALSE),0) -> 4 | W32: =-IFERROR(HLOOKUP(L32,Standings!$F$3:$BA$5,3,FALSE),0) -> -70 | X32: =SUM(N32:W32) -> 100
B33: Cà Phê Đen Kid | C33: Colombia | D33: Croatia | E33: New Zealand | F33: Japan | G33: Netherlands | N33: =IFERROR(HLOOKUP(C33,Standings!$F$3:$BA$5,3,FALSE),0) -> 25 | O33: =IFERROR(HLOOKUP(D33,Standings!$F$3:$BA$5,3,FALSE),0) -> 16 | P33: =IFERROR(HLOOKUP(E33,Standings!$F$3:$BA$5,3,FALSE),0) -> 4 | Q33: =IFERROR(HLOOKUP(F33,Standings!$F$3:$BA$5,3,FALSE),0) -> 20 | R33: =IFERROR(HLOOKUP(G33,Standings!$F$3:$BA$5,3,FALSE),0) -> 35 | S33: =IFERROR(HLOOKUP(H33,Standings!$F$3:$BA$5,3,FALSE),0) -> 0 | T33: =IFERROR(HLOOKUP(I33,Standings!$F$3:$BA$5,3,FALSE),0) -> 0 | U33: =IFERROR(HLOOKUP(J33,Standings!$F$3:$BA$5,3,FALSE),0) -> 0 | V33: =IFERROR(HLOOKUP(K33,Standings!$F$3:$BA$5,3,FALSE),0) -> 0 | W33: =-IFERROR(HLOOKUP(L33,Standings!$F$3:$BA$5,3,FALSE),0) -> 0 | X33: =SUM(N33:W33) -> 100
B34: AnaTwohy1 | C34: Argentina | D34: USA | E34: Belgium | L34: Paraguay | N34: =IFERROR(HLOOKUP(C34,Standings!$F$3:$BA$5,3,FALSE),0) -> 52 | O34: =IFERROR(HLOOKUP(D34,Standings!$F$3:$BA$5,3,FALSE),0) -> 23 | P34: =IFERROR(HLOOKUP(E34,Standings!$F$3:$BA$5,3,FALSE),0) -> 38 | Q34: =IFERROR(HLOOKUP(F34,Standings!$F$3:$BA$5,3,FALSE),0) -> 0 | R34: =IFERROR(HLOOKUP(G34,Standings!$F$3:$BA$5,3,FALSE),0) -> 0 | S34: =IFERROR(HLOOKUP(H34,Standings!$F$3:$BA$5,3,FALSE),0) -> 0 | T34: =IFERROR(HLOOKUP(I34,Standings!$F$3:$BA$5,3,FALSE),0) -> 0 | U34: =IFERROR(HLOOKUP(J34,Standings!$F$3:$BA$5,3,FALSE),0) -> 0 | V34: =IFERROR(HLOOKUP(K34,Standings!$F$3:$BA$5,3,FALSE),0) -> 0 | W34: =-IFERROR(HLOOKUP(L34,Standings!$F$3:$BA$5,3,FALSE),0) -> -13 | X34: =SUM(N34:W34) -> 100
B35: AnaTwohy2 | C35: England | D35: Brazil | L35: Sweden | N35: =IFERROR(HLOOKUP(C35,Standings!$F$3:$BA$5,3,FALSE),0) -> 60 | O35: =IFERROR(HLOOKUP(D35,Standings!$F$3:$BA$5,3,FALSE),0) -> 54 | P35: =IFERROR(HLOOKUP(E35,Standings!$F$3:$BA$5,3,FALSE),0) -> 0 | Q35: =IFERROR(HLOOKUP(F35,Standings!$F$3:$BA$5,3,FALSE),0) -> 0 | R35: =IFERROR(HLOOKUP(G35,Standings!$F$3:$BA$5,3,FALSE),0) -> 0 | S35: =IFERROR(HLOOKUP(H35,Standings!$F$3:$BA$5,3,FALSE),0) -> 0 | T35: =IFERROR(HLOOKUP(I35,Standings!$F$3:$BA$5,3,FALSE),0) -> 0 | U35: =IFERROR(HLOOKUP(J35,Standings!$F$3:$BA$5,3,FALSE),0) -> 0 | V35: =IFERROR(HLOOKUP(K35,Standings!$F$3:$BA$5,3,FALSE),0) -> 0 | W35: =-IFERROR(HLOOKUP(L35,Standings!$F$3:$BA$5,3,FALSE),0) -> -14 | X35: =SUM(N35:W35) -> 100
B36: JoshTwohy1 | C36: Netherlands | D36: Mexico | E36: Switzerland | F36: Japan | G36: Canada | H36: Croatia | I36: Austria | J36: Egypt | K36: Curaçao | L36: France | N36: =IFERROR(HLOOKUP(C36,Standings!$F$3:$BA$5,3,FALSE),0) -> 35 | O36: =IFERROR(HLOOKUP(D36,Standings!$F$3:$BA$5,3,FALSE),0) -> 27 | P36: =IFERROR(HLOOKUP(E36,Standings!$F$3:$BA$5,3,FALSE),0) -> 26 | Q36: =IFERROR(HLOOKUP(F36,Standings!$F$3:$BA$5,3,FALSE),0) -> 20 | R36: =IFERROR(HLOOKUP(G36,Standings!$F$3:$BA$5,3,FALSE),0) -> 19 | S36: =IFERROR(HLOOKUP(H36,Standings!$F$3:$BA$5,3,FALSE),0) -> 16 | T36: =IFERROR(HLOOKUP(I36,Standings!$F$3:$BA$5,3,FALSE),0) -> 12 | U36: =IFERROR(HLOOKUP(J36,Standings!$F$3:$BA$5,3,FALSE),0) -> 10 | V36: =IFERROR(HLOOKUP(K36,Standings!$F$3:$BA$5,3,FALSE),0) -> 3 | W36: =-IFERROR(HLOOKUP(L36,Standings!$F$3:$BA$5,3,FALSE),0) -> -68 | X36: =SUM(N36:W36) -> 100
B37: JoshTwohy2 | C37: France | D37: Spain | L37: Belgium | N37: =IFERROR(HLOOKUP(C37,Standings!$F$3:$BA$5,3,FALSE),0) -> 68 | O37: =IFERROR(HLOOKUP(D37,Standings!$F$3:$BA$5,3,FALSE),0) -> 70 | P37: =IFERROR(HLOOKUP(E37,Standings!$F$3:$BA$5,3,FALSE),0) -> 0 | Q37: =IFERROR(HLOOKUP(F37,Standings!$F$3:$BA$5,3,FALSE),0) -> 0 | R37: =IFERROR(HLOOKUP(G37,Standings!$F$3:$BA$5,3,FALSE),0) -> 0 | S37: =IFERROR(HLOOKUP(H37,Standings!$F$3:$BA$5,3,FALSE),0) -> 0 | T37: =IFERROR(HLOOKUP(I37,Standings!$F$3:$BA$5,3,FALSE),0) -> 0 | U37: =IFERROR(HLOOKUP(J37,Standings!$F$3:$BA$5,3,FALSE),0) -> 0 | V37: =IFERROR(HLOOKUP(K37,Standings!$F$3:$BA$5,3,FALSE),0) -> 0 | W37: =-IFERROR(HLOOKUP(L37,Standings!$F$3:$BA$5,3,FALSE),0) -> -38 | X37: =SUM(N37:W37) -> 100
B38: WillTwohy1 | C38: Belgium | D38: Netherlands | E38: France | F38: New Zealand | L38: Germany | N38: =IFERROR(HLOOKUP(C38,Standings!$F$3:$BA$5,3,FALSE),0) -> 38 | O38: =IFERROR(HLOOKUP(D38,Standings!$F$3:$BA$5,3,FALSE),0) -> 35 | P38: =IFERROR(HLOOKUP(E38,Standings!$F$3:$BA$5,3,FALSE),0) -> 68 | Q38: =IFERROR(HLOOKUP(F38,Standings!$F$3:$BA$5,3,FALSE),0) -> 4 | R38: =IFERROR(HLOOKUP(G38,Standings!$F$3:$BA$5,3,FALSE),0) -> 0 | S38: =IFERROR(HLOOKUP(H38,Standings!$F$3:$BA$5,3,FALSE),0) -> 0 | T38: =IFERROR(HLOOKUP(I38,Standings!$F$3:$BA$5,3,FALSE),0) -> 0 | U38: =IFERROR(HLOOKUP(J38,Standings!$F$3:$BA$5,3,FALSE),0) -> 0 | V38: =IFERROR(HLOOKUP(K38,Standings!$F$3:$BA$5,3,FALSE),0) -> 0 | W38: =-IFERROR(HLOOKUP(L38,Standings!$F$3:$BA$5,3,FALSE),0) -> -45 | X38: =SUM(N38:W38) -> 100
B39: WillTwohy2 | C39: Spain | D39: Mexico | E39: Uruguay | F39: Cape Verde | L39: Canada | N39: =IFERROR(HLOOKUP(C39,Standings!$F$3:$BA$5,3,FALSE),0) -> 70 | O39: =IFERROR(HLOOKUP(D39,Standings!$F$3:$BA$5,3,FALSE),0) -> 27 | P39: =IFERROR(HLOOKUP(E39,Standings!$F$3:$BA$5,3,FALSE),0) -> 18 | Q39: =IFERROR(HLOOKUP(F39,Standings!$F$3:$BA$5,3,FALSE),0) -> 4 | R39: =IFERROR(HLOOKUP(G39,Standings!$F$3:$BA$5,3,FALSE),0) -> 0 | S39: =IFERROR(HLOOKUP(H39,Standings!$F$3:$BA$5,3,FALSE),0) -> 0 | T39: =IFERROR(HLOOKUP(I39,Standings!$F$3:$BA$5,3,FALSE),0) -> 0 | U39: =IFERROR(HLOOKUP(J39,Standings!$F$3:$BA$5,3,FALSE),0) -> 0 | V39: =IFERROR(HLOOKUP(K39,Standings!$F$3:$BA$5,3,FALSE),0) -> 0 | W39: =-IFERROR(HLOOKUP(L39,Standings!$F$3:$BA$5,3,FALSE),0) -> -19 | X39: =SUM(N39:W39) -> 100
B40: Niedermaier_1A | C40: France | D40: Spain | E40: Croatia | L40: Brazil | N40: =IFERROR(HLOOKUP(C40,Standings!$F$3:$BA$5,3,FALSE),0) -> 68 | O40: =IFERROR(HLOOKUP(D40,Standings!$F$3:$BA$5,3,FALSE),0) -> 70 | P40: =IFERROR(HLOOKUP(E40,Standings!$F$3:$BA$5,3,FALSE),0) -> 16 | Q40: =IFERROR(HLOOKUP(F40,Standings!$F$3:$BA$5,3,FALSE),0) -> 0 | R40: =IFERROR(HLOOKUP(G40,Standings!$F$3:$BA$5,3,FALSE),0) -> 0 | S40: =IFERROR(HLOOKUP(H40,Standings!$F$3:$BA$5,3,FALSE),0) -> 0 | T40: =IFERROR(HLOOKUP(I40,Standings!$F$3:$BA$5,3,FALSE),0) -> 0 | U40: =IFERROR(HLOOKUP(J40,Standings!$F$3:$BA$5,3,FALSE),0) -> 0 | V40: =IFERROR(HLOOKUP(K40,Standings!$F$3:$BA$5,3,FALSE),0) -> 0 | W40: =-IFERROR(HLOOKUP(L40,Standings!$F$3:$BA$5,3,FALSE),0) -> -54 | X40: =SUM(N40:W40) -> 100
...

Sheet Standings
F2: Group A | J2: Group B | N2: Group C | R2: Group D | V2: Group E | Z2: Group F | AD2: Group G | AH2: Group H | AL2: Group I | AP2: Group J | AT2: Group K | AX2: Group L
D3: Rank | E3: Total Points | F3: Mexico | G3: South Africa | H3: South Korea | I3: Czechia | J3: Canada | K3: Switzerland | L3: Qatar | M3: Bosnia and Herzegovina | N3: Brazil | O3: Morocco | P3: Haiti | Q3: Scotland | R3: USA | S3: Paraguay | T3: Australia | U3: Türkiye | V3: Germany | W3: Curaçao | X3: Ivory Coast | Y3: Ecuador | Z3: Netherlands | AA3: Japan | AB3: Tunisia | AC3: Sweden | AD3: Belgium | AE3: Egypt | AF3: Iran | AG3: New Zealand | AH3: Spain | AI3: Cape Verde | AJ3: Saudi Arabia | AK3: Uruguay | AL3: France | AM3: Senegal | AN3: Norway | AO3: Iraq | AP3: Argentina | AQ3: Algeria | AR3: Austria | AS3: Jordan | AT3: Portugal | AU3: Uzbekistan | AV3: Colombia | AW3: DR Congo | AX3: England | AY3: Croatia | AZ3: Ghana | BA3: Panama | BB3: Paid in? | BC3: Payout | BD3: Net | BE3: Paid out? | BG3: Mexico | BH3: South Africa | BI3: South Korea | BJ3: Czechia | BK3: Canada | BL3: Switzerland | BM3: Qatar | BN3: Bosnia and Herzegovina | BO3: Brazil | BP3: Morocco | BQ3: Haiti | BR3: Scotland | BS3: USA | BT3: Paraguay | BU3: Australia | BV3: Türkiye | BW3: Germany | BX3: Curaçao | BY3: Ivory Coast | BZ3: Ecuador | CA3: Netherlands | CB3: Japan | CC3: Tunisia | CD3: Sweden | CE3: Belgium | CF3: Egypt | CG3: Iran | CH3: New Zealand | CI3: Spain | CJ3: Cape Verde | CK3: Saudi Arabia | CL3: Uruguay | CM3: France | CN3: Senegal | CO3: Norway | CP3: Iraq | CQ3: Argentina | CR3: Algeria | CS3: Austria | CT3: Jordan | CU3: Portugal | CV3: Uzbekistan | CW3: Colombia | CX3: DR Congo | CY3: England | CZ3: Croatia | DA3: Ghana | DB3: Panama
C4: Number Chosen | F4: =COUNTIF(#REF!,"x") -> #REF! | G4: =COUNTIF(#REF!,"x") -> #REF! | H4: =COUNTIF(#REF!,"x") -> #REF! | I4: =COUNTIF(#REF!,"x") -> #REF! | J4: =COUNTIF(#REF!,"x") -> #REF! | K4: =COUNTIF(#REF!,"x") -> #REF! | L4: =COUNTIF(#REF!,"x") -> #REF! | M4: =COUNTIF(#REF!,"x") -> #REF! | ... BA4: =COUNTIF(#REF!,"x") -> #REF!
C5: Price | F5: 27 | G5: 6 | H5: 11 | I5: 12 | J5: 19 | K5: 26 | L5: 3 | M5: 10 | N5: 54 | O5: 21 | P5: 5 | Q5: 9 | R5: 23 | S5: 13 | T5: 7 | U5: 20 | V5: 45 | W5: 3 | X5: 9 | Y5: 17 | Z5: 35 | AA5: 20 | AB5: 7 | AC5: 14 | AD5: 38 | AE5: 10 | AF5: 8 | AG5: 4 | AH5: 70 | AI5: 4 | AJ5: 5 | AK5: 18 | AL5: 68 | AM5: 13 | AN5: 30 | AO5: 5 | AP5: 52 | AQ5: 8 | AR5: 12 | AS5: 3 | AT5: 50 | AU5: 5 | AV5: 25 | AW5: 6 | AX5: 60 | AY5: 16 | AZ5: 7 | BA5: 5
C6: Points | F6: =HLOOKUP(F3,'Match Results'!$B$1:$AW$10,10,FALSE) -> 2 | G6: =HLOOKUP(G3,'Match Results'!$B$1:$AW$10,10,FALSE) -> 0 | H6: =HLOOKUP(H3,'Match Results'!$B$1:$AW$10,10,FALSE) -> 2 | I6: =HLOOKUP(I3,'Match Results'!$B$1:$AW$10,10,FALSE) -> 0 | J6: =HLOOKUP(J3,'Match Results'!$B$1:$AW$10,10,FALSE) -> 1 | K6: =HLOOKUP(K3,'Match Results'!$B$1:$AW$10,10,FALSE) -> 1 | L6: =HLOOKUP(L3,'Match Results'!$B$1:$AW$10,10,FALSE) -> 1 | M6: =HLOOKUP(M3,'Match Results'!$B$1:$AW$10,10,FALSE) -> 1 | ... BA6: =HLOOKUP(BA3,'Match Results'!$B$1:$AW$10,10,FALSE) -> 0
C7: # of times chosen | F7: =COUNTIF(BG:BG,"x") -> 21 | G7: =COUNTIF(BH:BH,"x") -> 2 | H7: =COUNTIF(BI:BI,"x") -> 14 | I7: =COUNTIF(BJ:BJ,"x") -> 8 | J7: =COUNTIF(BK:BK,"x") -> 17 | K7: =COUNTIF(BL:BL,"x") -> 17 | L7: =COUNTIF(BM:BM,"x") -> 7 | M7: =COUNTIF(BN:BN,"x") -> 2 | N7: =COUNTIF(BO:BO,"x") -> 9 | O7: =COUNTIF(BP:BP,"x") -> 24 | P7: =COUNTIF(BQ:BQ,"x") -> 1 | Q7: =COUNTIF(BR:BR,"x") -> 9 | R7: =COUNTIF(BS:BS,"x") -> 24 | S7: =COUNTIF(BT:BT,"x") -> 2 | T7: =COUNTIF(BU:BU,"x") -> 7 | U7: =COUNTIF(BV:BV,"x") -> 8 | V7: =COUNTIF(BW:BW,"x") -> 14 | W7: =COUNTIF(BX:BX,"x") -> 5 | X7: =COUNTIF(BY:BY,"x") -> 7 | Y7: =COUNTIF(BZ:BZ,"x") -> 23 | Z7: =COUNTIF(CA:CA,"x") -> 19 | AA7: =COUNTIF(CB:CB,"x") -> 29 | AB7: =COUNTIF(CC:CC,"x") -> 5 | AC7: =COUNTIF(CD:CD,"x") -> 6 | AD7: =COUNTIF(CE:CE,"x") -> 19 | AE7: =COUNTIF(CF:CF,"x") -> 18 | AF7: =COUNTIF(CG:CG,"x") -> 7 | AG7: =COUNTIF(CH:CH,"x") -> 7 | AH7: =COUNTIF(CI:CI,"x") -> 12 | AI7: =COUNTIF(CJ:CJ,"x") -> 4 | AJ7: =COUNTIF(CK:CK,"x") -> 2 | AK7: =COUNTIF(CL:CL,"x") -> 13 | AL7: =COUNTIF(CM:CM,"x") -> 21 | AM7: =COUNTIF(CN:CN,"x") -> 22 | AN7: =COUNTIF(CO:CO,"x") -> 13 | AO7: =COUNTIF(CP:CP,"x") -> 0 | AP7: =COUNTIF(CQ:CQ,"x") -> 15 | AQ7: =COUNTIF(CR:CR,"x") -> 6 | AR7: =COUNTIF(CS:CS,"x") -> 21 | AS7: =COUNTIF(CT:CT,"x") -> 6 | AT7: =COUNTIF(CU:CU,"x") -> 15 | AU7: =COUNTIF(CV:CV,"x") -> 1 | AV7: =COUNTIF(CW:CW,"x") -> 17 | AW7: =COUNTIF(CX:CX,"x") -> 5 | AX7: =COUNTIF(CY:CY,"x") -> 14 | AY7: =COUNTIF(CZ:CZ,"x") -> 29 | AZ7: =COUNTIF(DA:DA,"x") -> 3 | BA7: =COUNTIF(DB:DB,"x") -> 5
C8: # of times shorted | F8: =COUNTIF(BG:BG,"S") -> 0 | G8: =COUNTIF(BH:BH,"S") -> 1 | H8: =COUNTIF(BI:BI,"S") -> 0 | I8: =COUNTIF(BJ:BJ,"S") -> 1 | J8: =COUNTIF(BK:BK,"S") -> 1 | K8: =COUNTIF(BL:BL,"S") -> 1 | L8: =COUNTIF(BM:BM,"S") -> 1 | M8: =COUNTIF(BN:BN,"S") -> 1 | N8: =COUNTIF(BO:BO,"S") -> 5 | O8: =COUNTIF(BP:BP,"S") -> 1 | P8: =COUNTIF(BQ:BQ,"S") -> 0 | Q8: =COUNTIF(BR:BR,"S") -> 0 | R8: =COUNTIF(BS:BS,"S") -> 2 | S8: =COUNTIF(BT:BT,"S") -> 2 | T8: =COUNTIF(BU:BU,"S") -> 0 | U8: =COUNTIF(BV:BV,"S") -> 4 | V8: =COUNTIF(BW:BW,"S") -> 7 | W8: =COUNTIF(BX:BX,"S") -> 0 | X8: =COUNTIF(BY:BY,"S") -> 0 | Y8: =COUNTIF(BZ:BZ,"S") -> 0 | Z8: =COUNTIF(CA:CA,"S") -> 6 | AA8: =COUNTIF(CB:CB,"S") -> 3 | AB8: =COUNTIF(CC:CC,"S") -> 0 | AC8: =COUNTIF(CD:CD,"S") -> 3 | AD8: =COUNTIF(CE:CE,"S") -> 5 | AE8: =COUNTIF(CF:CF,"S") -> 0 | AF8: =COUNTIF(CG:CG,"S") -> 1 | AG8: =COUNTIF(CH:CH,"S") -> 0 | AH8: =COUNTIF(CI:CI,"S") -> 6 | AI8: =COUNTIF(CJ:CJ,"S") -> 0 | AJ8: =COUNTIF(CK:CK,"S") -> 0 | AK8: =COUNTIF(CL:CL,"S") -> 0 | AL8: =COUNTIF(CM:CM,"S") -> 10 | AM8: =COUNTIF(CN:CN,"S") -> 2 | AN8: =COUNTIF(CO:CO,"S") -> 5 | AO8: =COUNTIF(CP:CP,"S") -> 0 | AP8: =COUNTIF(CQ:CQ,"S") -> 6 | AQ8: =COUNTIF(CR:CR,"S") -> 0 | AR8: =COUNTIF(CS:CS,"S") -> 0 | AS8: =COUNTIF(CT:CT,"S") -> 2 | AT8: =COUNTIF(CU:CU,"S") -> 8 | AU8: =COUNTIF(CV:CV,"S") -> 0 | AV8: =COUNTIF(CW:CW,"S") -> 1 | AW8: =COUNTIF(CX:CX,"S") -> 0 | AX8: =COUNTIF(CY:CY,"S") -> 8 | AY8: =COUNTIF(CZ:CZ,"S") -> 0 | AZ8: =COUNTIF(DA:DA,"S") -> 0 | BA8: =COUNTIF(DB:DB,"S") -> 0
C9: Points Earned / Price | F9: =F6/F5 -> 0.074074074 | G9: =G6/G5 -> 0 | H9: =H6/H5 -> 0.18181818 | I9: =I6/I5 -> 0 | J9: =J6/J5 -> 0.052631579 | K9: =K6/K5 -> 0.038461538 | L9: =L6/L5 -> 0.33333333 | M9: =M6/M5 -> 0.1 | ... BA9: =BA6/BA5 -> 0
B10: 26 | C10: =Entries!B91 -> NTourville1 | D10: =IF(C10="","",RANK(E10,$E$10:$E$111)) -> 1 | E10: =IF(C10="","",ROUND(SUM(F10:AK10),0)) -> 9 | F10: =IF(BG10="","",IF(BG10="x",F$6,0)+IF(BG10="S",-F$6-0.00001,0)) -> 2 | G10: =IF(BH10="","",IF(BH10="x",G$6,0)+IF(BH10="S",-G$6-0.00001,0)) -> 0 | H10: =IF(BI10="","",IF(BI10="x",H$6,0)+IF(BI10="S",-H$6-0.00001,0)) -> 2 | I10: =IF(BJ10="","",IF(BJ10="x",I$6,0)+IF(BJ10="S",-I$6-0.00001,0)) -> 0 | J10: =IF(BK10="","",IF(BK10="x",J$6,0)+IF(BK10="S",-J$6-0.00001,0)) -> 1 | K10: =IF(BL10="","",IF(BL10="x",K$6,0)+IF(BL10="S",-K$6-0.00001,0)) -> 1 | L10: =IF(BM10="","",IF(BM10="x",L$6,0)+IF(BM10="S",-L$6-0.00001,0)) -> 1 | M10: =IF(BN10="","",IF(BN10="x",M$6,0)+IF(BN10="S",-M$6-0.00001,0)) -> 1 | ... BA10: =IF(DB10="","",IF(DB10="x",BA$6,0)+IF(DB10="S",-BA$6-0.00001,0)) | BB10: No | BG10: =IF(NOT(ISERROR(HLOOKUP(Standings!BG$3,Entries!$C91:$K91,1,FALSE))),"x",IF(NOT(ISERROR(HLOOKUP(Standings!BG$3,Entries!$L91:$L91,1,FALSE))),"S","")) -> x | BH10: =IF(NOT(ISERROR(HLOOKUP(Standings!BH$3,Entries!$C91:$K91,1,FALSE))),"x",IF(NOT(ISERROR(HLOOKUP(Standings!BH$3,Entries!$L91:$L91,1,FALSE))),"S","")) -> x | BI10: =IF(NOT(ISERROR(HLOOKUP(Standings!BI$3,Entries!$C91:$K91,1,FALSE))),"x",IF(NOT(ISERROR(HLOOKUP(Standings!BI$3,Entries!$L91:$L91,1,FALSE))),"S","")) -> x | BJ10: =IF(NOT(ISERROR(HLOOKUP(Standings!BJ$3,Entries!$C91:$K91,1,FALSE))),"x",IF(NOT(ISERROR(HLOOKUP(Standings!BJ$3,Entries!$L91:$L91,1,FALSE))),"S","")) -> x | BK10: =IF(NOT(ISERROR(HLOOKUP(Standings!BK$3,Entries!$C91:$K91,1,FALSE))),"x",IF(NOT(ISERROR(HLOOKUP(Standings!BK$3,Entries!$L91:$L91,1,FALSE))),"S","")) -> x | BL10: =IF(NOT(ISERROR(HLOOKUP(Standings!BL$3,Entries!$C91:$K91,1,FALSE))),"x",IF(NOT(ISERROR(HLOOKUP(Standings!BL$3,Entries!$L91:$L91,1,FALSE))),"S","")) -> x | BM10: =IF(NOT(ISERROR(HLOOKUP(Standings!BM$3,Entries!$C91:$K91,1,FALSE))),"x",IF(NOT(ISERROR(HLOOKUP(Standings!BM$3,Entries!$L91:$L91,1,FALSE))),"S","")) -> x | BN10: =IF(NOT(ISERROR(HLOOKUP(Standings!BN$3,Entries!$C91:$K91,1,FALSE))),"x",IF(NOT(ISERROR(HLOOKUP(Standings!BN$3,Entries!$L91:$L91,1,FALSE))),"S","")) -> x | ... DB10: =IF(NOT(ISERROR(HLOOKUP(Standings!DB$3,Entries!$C91:$K91,1,FALSE))),"x",IF(NOT(ISERROR(HLOOKUP(Standings!DB$3,Entries!$L91:$L91,1,FALSE))),"S",""))
B11: 18 | C11: =Entries!B31 -> Sean ODonnell1 | D11: =IF(C11="","",RANK(E11,$E$10:$E$111)) -> 1 | E11: =IF(C11="","",ROUND(SUM(F11:AK11),0)) -> 9 | F11: =IF(BG11="","",IF(BG11="x",F$6,0)+IF(BG11="S",-F$6-0.00001,0)) | G11: =IF(BH11="","",IF(BH11="x",G$6,0)+IF(BH11="S",-G$6-0.00001,0)) | H11: =IF(BI11="","",IF(BI11="x",H$6,0)+IF(BI11="S",-H$6-0.00001,0)) -> 2 | I11: =IF(BJ11="","",IF(BJ11="x",I$6,0)+IF(BJ11="S",-I$6-0.00001,0)) | J11: =IF(BK11="","",IF(BK11="x",J$6,0)+IF(BK11="S",-J$6-0.00001,0)) | K11: =IF(BL11="","",IF(BL11="x",K$6,0)+IF(BL11="S",-K$6-0.00001,0)) -> 1 | L11: =IF(BM11="","",IF(BM11="x",L$6,0)+IF(BM11="S",-L$6-0.00001,0)) | M11: =IF(BN11="","",IF(BN11="x",M$6,0)+IF(BN11="S",-M$6-0.00001,0)) | ... BA11: =IF(DB11="","",IF(DB11="x",BA$6,0)+IF(DB11="S",-BA$6-0.00001,0)) | BB11: No | BG11: =IF(NOT(ISERROR(HLOOKUP(Standings!BG$3,Entries!$C31:$K31,1,FALSE))),"x",IF(NOT(ISERROR(HLOOKUP(Standings!BG$3,Entries!$L31:$L31,1,FALSE))),"S","")) | BH11: =IF(NOT(ISERROR(HLOOKUP(Standings!BH$3,Entries!$C31:$K31,1,FALSE))),"x",IF(NOT(ISERROR(HLOOKUP(Standings!BH$3,Entries!$L31:$L31,1,FALSE))),"S","")) | BI11: =IF(NOT(ISERROR(HLOOKUP(Standings!BI$3,Entries!$C31:$K31,1,FALSE))),"x",IF(NOT(ISERROR(HLOOKUP(Standings!BI$3,Entries!$L31:$L31,1,FALSE))),"S","")) -> x | BJ11: =IF(NOT(ISERROR(HLOOKUP(Standings!BJ$3,Entries!$C31:$K31,1,FALSE))),"x",IF(NOT(ISERROR(HLOOKUP(Standings!BJ$3,Entries!$L31:$L31,1,FALSE))),"S","")) | BK11: =IF(NOT(ISERROR(HLOOKUP(Standings!BK$3,Entries!$C31:$K31,1,FALSE))),"x",IF(NOT(ISERROR(HLOOKUP(Standings!BK$3,Entries!$L31:$L31,1,FALSE))),"S","")) | BL11: =IF(NOT(ISERROR(HLOOKUP(Standings!BL$3,Entries!$C31:$K31,1,FALSE))),"x",IF(NOT(ISERROR(HLOOKUP(Standings!BL$3,Entries!$L31:$L31,1,FALSE))),"S","")) -> x | BM11: =IF(NOT(ISERROR(HLOOKUP(Standings!BM$3,Entries!$C31:$K31,1,FALSE))),"x",IF(NOT(ISERROR(HLOOKUP(Standings!BM$3,Entries!$L31:$L31,1,FALSE))),"S","")) | BN11: =IF(NOT(ISERROR(HLOOKUP(Standings!BN$3,Entries!$C31:$K31,1,FALSE))),"x",IF(NOT(ISERROR(HLOOKUP(Standings!BN$3,Entries!$L31:$L31,1,FALSE))),"S","")) | ... DB11: =IF(NOT(ISERROR(HLOOKUP(Standings!DB$3,Entries!$C31:$K31,1,FALSE))),"x",IF(NOT(ISERROR(HLOOKUP(Standings!DB$3,Entries!$L31:$L31,1,FALSE))),"S",""))
B12: 2 | C12: =Entries!B12 -> NickHanson2 | D12: =IF(C12="","",RANK(E12,$E$10:$E$111)) -> 3 | E12: =IF(C12="","",ROUND(SUM(F12:AK12),0)) -> 8 | F12: =IF(BG12="","",IF(BG12="x",F$6,0)+IF(BG12="S",-F$6-0.00001,0)) -> 2 | G12: =IF(BH12="","",IF(BH12="x",G$6,0)+IF(BH12="S",-G$6-0.00001,0)) | H12: =IF(BI12="","",IF(BI12="x",H$6,0)+IF(BI12="S",-H$6-0.00001,0)) | I12: =IF(BJ12="","",IF(BJ12="x",I$6,0)+IF(BJ12="S",-I$6-0.00001,0)) | J12: =IF(BK12="","",IF(BK12="x",J$6,0)+IF(BK12="S",-J$6-0.00001,0)) | K12: =IF(BL12="","",IF(BL12="x",K$6,0)+IF(BL12="S",-K$6-0.00001,0)) | L12: =IF(BM12="","",IF(BM12="x",L$6,0)+IF(BM12="S",-L$6-0.00001,0)) | M12: =IF(BN12="","",IF(BN12="x",M$6,0)+IF(BN12="S",-M$6-0.00001,0)) | ... BA12: =IF(DB12="","",IF(DB12="x",BA$6,0)+IF(DB12="S",-BA$6-0.00001,0)) | BB12: No | BG12: =IF(NOT(ISERROR(HLOOKUP(Standings!BG$3,Entries!$C12:$K12,1,FALSE))),"x",IF(NOT(ISERROR(HLOOKUP(Standings!BG$3,Entries!$L12:$L12,1,FALSE))),"S","")) -> x | BH12: =IF(NOT(ISERROR(HLOOKUP(Standings!BH$3,Entries!$C12:$K12,1,FALSE))),"x",IF(NOT(ISERROR(HLOOKUP(Standings!BH$3,Entries!$L12:$L12,1,FALSE))),"S","")) | BI12: =IF(NOT(ISERROR(HLOOKUP(Standings!BI$3,Entries!$C12:$K12,1,FALSE))),"x",IF(NOT(ISERROR(HLOOKUP(Standings!BI$3,Entries!$L12:$L12,1,FALSE))),"S","")) | BJ12: =IF(NOT(ISERROR(HLOOKUP(Standings!BJ$3,Entries!$C12:$K12,1,FALSE))),"x",IF(NOT(ISERROR(HLOOKUP(Standings!BJ$3,Entries!$L12:$L12,1,FALSE))),"S","")) | BK12: =IF(NOT(ISERROR(HLOOKUP(Standings!BK$3,Entries!$C12:$K12,1,FALSE))),"x",IF(NOT(ISERROR(HLOOKUP(Standings!BK$3,Entries!$L12:$L12,1,FALSE))),"S","")) | BL12: =IF(NOT(ISERROR(HLOOKUP(Standings!BL$3,Entries!$C12:$K12,1,FALSE))),"x",IF(NOT(ISERROR(HLOOKUP(Standings!BL$3,Entries!$L12:$L12,1,FALSE))),"S","")) | BM12: =IF(NOT(ISERROR(HLOOKUP(Standings!BM$3,Entries!$C12:$K12,1,FALSE))),"x",IF(NOT(ISERROR(HLOOKUP(Standings!BM$3,Entries!$L12:$L12,1,FALSE))),"S","")) | BN12: =IF(NOT(ISERROR(HLOOKUP(Standings!BN$3,Entries!$C12:$K12,1,FALSE))),"x",IF(NOT(ISERROR(HLOOKUP(Standings!BN$3,Entries!$L12:$L12,1,FALSE))),"S","")) | ... DB12: =IF(NOT(ISERROR(HLOOKUP(Standings!DB$3,Entries!$C12:$K12,1,FALSE))),"x",IF(NOT(ISERROR(HLOOKUP(Standings!DB$3,Entries!$L12:$L12,1,FALSE))),"S",""))
B13: 39 | C13: =Entries!B32 -> Sean ODonnell2 | D13: =IF(C13="","",RANK(E13,$E$10:$E$111)) -> 3 | E13: =IF(C13="","",ROUND(SUM(F13:AK13),0)) -> 8 | F13: =IF(BG13="","",IF(BG13="x",F$6,0)+IF(BG13="S",-F$6-0.00001,0)) | G13: =IF(BH13="","",IF(BH13="x",G$6,0)+IF(BH13="S",-G$6-0.00001,0)) | H13: =IF(BI13="","",IF(BI13="x",H$6,0)+IF(BI13="S",-H$6-0.00001,0)) | I13: =IF(BJ13="","",IF(BJ13="x",I$6,0)+IF(BJ13="S",-I$6-0.00001,0)) | J13: =IF(BK13="","",IF(BK13="x",J$6,0)+IF(BK13="S",-J$6-0.00001,0)) | K13: =IF(BL13="","",IF(BL13="x",K$6,0)+IF(BL13="S",-K$6-0.00001,0)) | L13: =IF(BM13="","",IF(BM13="x",L$6,0)+IF(BM13="S",-L$6-0.00001,0)) | M13: =IF(BN13="","",IF(BN13="x",M$6,0)+IF(BN13="S",-M$6-0.00001,0)) | ... BA13: =IF(DB13="","",IF(DB13="x",BA$6,0)+IF(DB13="S",-BA$6-0.00001,0)) | BB13: No | BG13: =IF(NOT(ISERROR(HLOOKUP(Standings!BG$3,Entries!$C32:$K32,1,FALSE))),"x",IF(NOT(ISERROR(HLOOKUP(Standings!BG$3,Entries!$L32:$L32,1,FALSE))),"S","")) | BH13: =IF(NOT(ISERROR(HLOOKUP(Standings!BH$3,Entries!$C32:$K32,1,FALSE))),"x",IF(NOT(ISERROR(HLOOKUP(Standings!BH$3,Entries!$L32:$L32,1,FALSE))),"S","")) | BI13: =IF(NOT(ISERROR(HLOOKUP(Standings!BI$3,Entries!$C32:$K32,1,FALSE))),"x",IF(NOT(ISERROR(HLOOKUP(Standings!BI$3,Entries!$L32:$L32,1,FALSE))),"S","")) | BJ13: =IF(NOT(ISERROR(HLOOKUP(Standings!BJ$3,Entries!$C32:$K32,1,FALSE))),"x",IF(NOT(ISERROR(HLOOKUP(Standings!BJ$3,Entries!$L32:$L32,1,FALSE))),"S","")) | BK13: =IF(NOT(ISERROR(HLOOKUP(Standings!BK$3,Entries!$C32:$K32,1,FALSE))),"x",IF(NOT(ISERROR(HLOOKUP(Standings!BK$3,Entries!$L32:$L32,1,FALSE))),"S","")) | BL13: =IF(NOT(ISERROR(HLOOKUP(Standings!BL$3,Entries!$C32:$K32,1,FALSE))),"x",IF(NOT(ISERROR(HLOOKUP(Standings!BL$3,Entries!$L32:$L32,1,FALSE))),"S","")) | BM13: =IF(NOT(ISERROR(HLOOKUP(Standings!BM$3,Entries!$C32:$K32,1,FALSE))),"x",IF(NOT(ISERROR(HLOOKUP(Standings!BM$3,Entries!$L32:$L32,1,FALSE))),"S","")) | BN13: =IF(NOT(ISERROR(HLOOKUP(Standings!BN$3,Entries!$C32:$K32,1,FALSE))),"x",IF(NOT(ISERROR(HLOOKUP(Standings!BN$3,Entries!$L32:$L32,1,FALSE))),"S","")) | ... DB13: =IF(NOT(ISERROR(HLOOKUP(Standings!DB$3,Entries!$C32:$K32,1,FALSE))),"x",IF(NOT(ISERROR(HLOOKUP(Standings!DB$3,Entries!$L32:$L32,1,FALSE))),"S",""))
B14: 63 | C14: =Entries!B2 -> Corey Strand | D14: =IF(C14="","",RANK(E14,$E$10:$E$111)) -> 5 | E14: =IF(C14="","",ROUND(SUM(F14:AK14),0)) -> 7 | F14: =IF(BG14="","",IF(BG14="x",F$6,0)+IF(BG14="S",-F$6-0.00001,0)) -> 2 | G14: =IF(BH14="","",IF(BH14="x",G$6,0)+IF(BH14="S",-G$6-0.00001,0)) | H14: =IF(BI14="","",IF(BI14="x",H$6,0)+IF(BI14="S",-H$6-0.00001,0)) | I14: =IF(BJ14="","",IF(BJ14="x",I$6,0)+IF(BJ14="S",-I$6-0.00001,0)) | J14: =IF(BK14="","",IF(BK14="x",J$6,0)+IF(BK14="S",-J$6-0.00001,0)) | K14: =IF(BL14="","",IF(BL14="x",K$6,0)+IF(BL14="S",-K$6-0.00001,0)) | L14: =IF(BM14="","",IF(BM14="x",L$6,0)+IF(BM14="S",-L$6-0.00001,0)) -> 1 | M14: =IF(BN14="","",IF(BN14="x",M$6,0)+IF(BN14="S",-M$6-0.00001,0)) | ... BA14: =IF(DB14="","",IF(DB14="x",BA$6,0)+IF(DB14="S",-BA$6-0.00001,0)) | BB14: No | BG14: =IF(NOT(ISERROR(HLOOKUP(Standings!BG$3,Entries!$C2:$K2,1,FALSE))),"x",IF(NOT(ISERROR(HLOOKUP(Standings!BG$3,Entries!$L2:$L2,1,FALSE))),"S","")) -> x | BH14: =IF(NOT(ISERROR(HLOOKUP(Standings!BH$3,Entries!$C2:$K2,1,FALSE))),"x",IF(NOT(ISERROR(HLOOKUP(Standings!BH$3,Entries!$L2:$L2,1,FALSE))),"S","")) | BI14: =IF(NOT(ISERROR(HLOOKUP(Standings!BI$3,Entries!$C2:$K2,1,FALSE))),"x",IF(NOT(ISERROR(HLOOKUP(Standings!BI$3,Entries!$L2:$L2,1,FALSE))),"S","")) | BJ14: =IF(NOT(ISERROR(HLOOKUP(Standings!BJ$3,Entries!$C2:$K2,1,FALSE))),"x",IF(NOT(ISERROR(HLOOKUP(Standings!BJ$3,Entries!$L2:$L2,1,FALSE))),"S","")) | BK14: =IF(NOT(ISERROR(HLOOKUP(Standings!BK$3,Entries!$C2:$K2,1,FALSE))),"x",IF(NOT(ISERROR(HLOOKUP(Standings!BK$3,Entries!$L2:$L2,1,FALSE))),"S","")) | BL14: =IF(NOT(ISERROR(HLOOKUP(Standings!BL$3,Entries!$C2:$K2,1,FALSE))),"x",IF(NOT(ISERROR(HLOOKUP(Standings!BL$3,Entries!$L2:$L2,1,FALSE))),"S","")) | BM14: =IF(NOT(ISERROR(HLOOKUP(Standings!BM$3,Entries!$C2:$K2,1,FALSE))),"x",IF(NOT(ISERROR(HLOOKUP(Standings!BM$3,Entries!$L2:$L2,1,FALSE))),"S","")) -> x | BN14: =IF(NOT(ISERROR(HLOOKUP(Standings!BN$3,Entries!$C2:$K2,1,FALSE))),"x",IF(NOT(ISERROR(HLOOKUP(Standings!BN$3,Entries!$L2:$L2,1,FALSE))),"S","")) | ... DB14: =IF(NOT(ISERROR(HLOOKUP(Standings!DB$3,Entries!$C2:$K2,1,FALSE))),"x",IF(NOT(ISERROR(HLOOKUP(Standings!DB$3,Entries!$L2:$L2,1,FALSE))),"S",""))
B15: 38 | C15: =Entries!B17 -> JoelsBigShort | D15: =IF(C15="","",RANK(E15,$E$10:$E$111)) -> 5 | E15: =IF(C15="","",ROUND(SUM(F15:AK15),0)) -> 7 | F15: =IF(BG15="","",IF(BG15="x",F$6,0)+IF(BG15="S",-F$6-0.00001,0)) -> 2 | G15: =IF(BH15="","",IF(BH15="x",G$6,0)+IF(BH15="S",-G$6-0.00001,0)) | H15: =IF(BI15="","",IF(BI15="x",H$6,0)+IF(BI15="S",-H$6-0.00001,0)) | I15: =IF(BJ15="","",IF(BJ15="x",I$6,0)+IF(BJ15="S",-I$6-0.00001,0)) | J15: =IF(BK15="","",IF(BK15="x",J$6,0)+IF(BK15="S",-J$6-0.00001,0)) -> 1 | K15: =IF(BL15="","",IF(BL15="x",K$6,0)+IF(BL15="S",-K$6-0.00001,0)) -> 1 | L15: =IF(BM15="","",IF(BM15="x",L$6,0)+IF(BM15="S",-L$6-0.00001,0)) | M15: =IF(BN15="","",IF(BN15="x",M$6,0)+IF(BN15="S",-M$6-0.00001,0)) | ... BA15: =IF(DB15="","",IF(DB15="x",BA$6,0)+IF(DB15="S",-BA$6-0.00001,0)) | BB15: No | BG15: =IF(NOT(ISERROR(HLOOKUP(Standings!BG$3,Entries!$C17:$K17,1,FALSE))),"x",IF(NOT(ISERROR(HLOOKUP(Standings!BG$3,Entries!$L17:$L17,1,FALSE))),"S","")) -> x | BH15: =IF(NOT(ISERROR(HLOOKUP(Standings!BH$3,Entries!$C17:$K17,1,FALSE))),"x",IF(NOT(ISERROR(HLOOKUP(Standings!BH$3,Entries!$L17:$L17,1,FALSE))),"S","")) | BI15: =IF(NOT(ISERROR(HLOOKUP(Standings!BI$3,Entries!$C17:$K17,1,FALSE))),"x",IF(NOT(ISERROR(HLOOKUP(Standings!BI$3,Entries!$L17:$L17,1,FALSE))),"S","")) | BJ15: =IF(NOT(ISERROR(HLOOKUP(Standings!BJ$3,Entries!$C17:$K17,1,FALSE))),"x",IF(NOT(ISERROR(HLOOKUP(Standings!BJ$3,Entries!$L17:$L17,1,FALSE))),"S","")) | BK15: =IF(NOT(ISERROR(HLOOKUP(Standings!BK$3,Entries!$C17:$K17,1,FALSE))),"x",IF(NOT(ISERROR(HLOOKUP(Standings!BK$3,Entries!$L17:$L17,1,FALSE))),"S","")) -> x | BL15: =IF(NOT(ISERROR(HLOOKUP(Standings!BL$3,Entries!$C17:$K17,1,FALSE))),"x",IF(NOT(ISERROR(HLOOKUP(Standings!BL$3,Entries!$L17:$L17,1,FALSE))),"S","")) -> x | BM15: =IF(NOT(ISERROR(HLOOKUP(Standings!BM$3,Entries!$C17:$K17,1,FALSE))),"x",IF(NOT(ISERROR(HLOOKUP(Standings!BM$3,Entries!$L17:$L17,1,FALSE))),"S","")) | BN15: =IF(NOT(ISERROR(HLOOKUP(Standings!BN$3,Entries!$C17:$K17,1,FALSE))),"x",IF(NOT(ISERROR(HLOOKUP(Standings!BN$3,Entries!$L17:$L17,1,FALSE))),"S","")) | ... DB15: =IF(NOT(ISERROR(HLOOKUP(Standings!DB$3,Entries!$C17:$K17,1,FALSE))),"x",IF(NOT(ISERROR(HLOOKUP(Standings!DB$3,Entries!$L17:$L17,1,FALSE))),"S",""))
B16: 16 | C16: =Entries!B36 -> JoshTwohy1 | D16: =IF(C16="","",RANK(E16,$E$10:$E$111)) -> 5 | E16: =IF(C16="","",ROUND(SUM(F16:AK16),0)) -> 7 | F16: =IF(BG16="","",IF(BG16="x",F$6,0)+IF(BG16="S",-F$6-0.00001,0)) -> 2 | G16: =IF(BH16="","",IF(BH16="x",G$6,0)+IF(BH16="S",-G$6-0.00001,0)) | H16: =IF(BI16="","",IF(BI16="x",H$6,0)+IF(BI16="S",-H$6-0.00001,0)) | I16: =IF(BJ16="","",IF(BJ16="x",I$6,0)+IF(BJ16="S",-I$6-0.00001,0)) | J16: =IF(BK16="","",IF(BK16="x",J$6,0)+IF(BK16="S",-J$6-0.00001,0)) -> 1 | K16: =IF(BL16="","",IF(BL16="x",K$6,0)+IF(BL16="S",-K$6-0.00001,0)) -> 1 | L16: =IF(BM16="","",IF(BM16="x",L$6,0)+IF(BM16="S",-L$6-0.00001,0)) | M16: =IF(BN16="","",IF(BN16="x",M$6,0)+IF(BN16="S",-M$6-0.00001,0)) | ... BA16: =IF(DB16="","",IF(DB16="x",BA$6,0)+IF(DB16="S",-BA$6-0.00001,0)) | BB16: No | BG16: =IF(NOT(ISERROR(HLOOKUP(Standings!BG$3,Entries!$C36:$K36,1,FALSE))),"x",IF(NOT(ISERROR(HLOOKUP(Standings!BG$3,Entries!$L36:$L36,1,FALSE))),"S","")) -> x | BH16: =IF(NOT(ISERROR(HLOOKUP(Standings!BH$3,Entries!$C36:$K36,1,FALSE))),"x",IF(NOT(ISERROR(HLOOKUP(Standings!BH$3,Entries!$L36:$L36,1,FALSE))),"S","")) | BI16: =IF(NOT(ISERROR(HLOOKUP(Standings!BI$3,Entries!$C36:$K36,1,FALSE))),"x",IF(NOT(ISERROR(HLOOKUP(Standings!BI$3,Entries!$L36:$L36,1,FALSE))),"S","")) | BJ16: =IF(NOT(ISERROR(HLOOKUP(Standings!BJ$3,Entries!$C36:$K36,1,FALSE))),"x",IF(NOT(ISERROR(HLOOKUP(Standings!BJ$3,Entries!$L36:$L36,1,FALSE))),"S","")) | BK16: =IF(NOT(ISERROR(HLOOKUP(Standings!BK$3,Entries!$C36:$K36,1,FALSE))),"x",IF(NOT(ISERROR(HLOOKUP(Standings!BK$3,Entries!$L36:$L36,1,FALSE))),"S","")) -> x | BL16: =IF(NOT(ISERROR(HLOOKUP(Standings!BL$3,Entries!$C36:$K36,1,FALSE))),"x",IF(NOT(ISERROR(HLOOKUP(Standings!BL$3,Entries!$L36:$L36,1,FALSE))),"S","")) -> x | BM16: =IF(NOT(ISERROR(HLOOKUP(Standings!BM$3,Entries!$C36:$K36,1,FALSE))),"x",IF(NOT(ISERROR(HLOOKUP(Standings!BM$3,Entries!$L36:$L36,1,FALSE))),"S","")) | BN16: =IF(NOT(ISERROR(HLOOKUP(Standings!BN$3,Entries!$C36:$K36,1,FALSE))),"x",IF(NOT(ISERROR(HLOOKUP(Standings!BN$3,Entries!$L36:$L36,1,FALSE))),"S","")) | ... DB16: =IF(NOT(ISERROR(HLOOKUP(Standings!DB$3,Entries!$C36:$K36,1,FALSE))),"x",IF(NOT(ISERROR(HLOOKUP(Standings!DB$3,Entries!$L36:$L36,1,FALSE))),"S",""))
B17: 13 | C17: =Entries!B41 -> Niedermaier_2B | D17: =IF(C17="","",RANK(E17,$E$10:$E$111)) -> 5 | E17: =IF(C17="","",ROUND(SUM(F17:AK17),0)) -> 7 | F17: =IF(BG17="","",IF(BG17="x",F$6,0)+IF(BG17="S",-F$6-0.00001,0)) | G17: =IF(BH17="","",IF(BH17="x",G$6,0)+IF(BH17="S",-G$6-0.00001,0)) | H17: =IF(BI17="","",IF(BI17="x",H$6,0)+IF(BI17="S",-H$6-0.00001,0)) | I17: =IF(BJ17="","",IF(BJ17="x",I$6,0)+IF(BJ17="S",-I$6-0.00001,0)) | J17: =IF(BK17="","",IF(BK17="x",J$6,0)+IF(BK17="S",-J$6-0.00001,0)) | K17: =IF(BL17="","",IF(BL17="x",K$6,0)+IF(BL17="S",-K$6-0.00001,0)) | L17: =IF(BM17="","",IF(BM17="x",L$6,0)+IF(BM17="S",-L$6-0.00001,0)) | M17: =IF(BN17="","",IF(BN17="x",M$6,0)+IF(BN17="S",-M$6-0.00001,0)) | ... BA17: =IF(DB17="","",IF(DB17="x",BA$6,0)+IF(DB17="S",-BA$6-0.00001,0)) | BB17: No | BG17: =IF(NOT(ISERROR(HLOOKUP(Standings!BG$3,Entries!$C41:$K41,1,FALSE))),"x",IF(NOT(ISERROR(HLOOKUP(Standings!BG$3,Entries!$L41:$L41,1,FALSE))),"S","")) | BH17: =IF(NOT(ISERROR(HLOOKUP(Standings!BH$3,Entries!$C41:$K41,1,FALSE))),"x",IF(NOT(ISERROR(HLOOKUP(Standings!BH$3,Entries!$L41:$L41,1,FALSE))),"S","")) | BI17: =IF(NOT(ISERROR(HLOOKUP(Standings!BI$3,Entries!$C41:$K41,1,FALSE))),"x",IF(NOT(ISERROR(HLOOKUP(Standings!BI$3,Entries!$L41:$L41,1,FALSE))),"S","")) | BJ17: =IF(NOT(ISERROR(HLOOKUP(Standings!BJ$3,Entries!$C41:$K41,1,FALSE))),"x",IF(NOT(ISERROR(HLOOKUP(Standings!BJ$3,Entries!$L41:$L41,1,FALSE))),"S","")) | BK17: =IF(NOT(ISERROR(HLOOKUP(Standings!BK$3,Entries!$C41:$K41,1,FALSE))),"x",IF(NOT(ISERROR(HLOOKUP(Standings!BK$3,Entries!$L41:$L41,1,FALSE))),"S","")) | BL17: =IF(NOT(ISERROR(HLOOKUP(Standings!BL$3,Entries!$C41:$K41,1,FALSE))),"x",IF(NOT(ISERROR(HLOOKUP(Standings!BL$3,Entries!$L41:$L41,1,FALSE))),"S","")) | BM17: =IF(NOT(ISERROR(HLOOKUP(Standings!BM$3,Entries!$C41:$K41,1,FALSE))),"x",IF(NOT(ISERROR(HLOOKUP(Standings!BM$3,Entries!$L41:$L41,1,FALSE))),"S","")) | BN17: =IF(NOT(ISERROR(HLOOKUP(Standings!BN$3,Entries!$C41:$K41,1,FALSE))),"x",IF(NOT(ISERROR(HLOOKUP(Standings!BN$3,Entries!$L41:$L41,1,FALSE))),"S","")) | ... DB17: =IF(NOT(ISERROR(HLOOKUP(Standings!DB$3,Entries!$C41:$K41,1,FALSE))),"x",IF(NOT(ISERROR(HLOOKUP(Standings!DB$3,Entries!$L41:$L41,1,FALSE))),"S",""))
B18: 44 | C18: =Entries!B52 -> ZachSchaefer1 | D18: =IF(C18="","",RANK(E18,$E$10:$E$111)) -> 5 | E18: =IF(C18="","",ROUND(SUM(F18:AK18),0)) -> 7 | F18: =IF(BG18="","",IF(BG18="x",F$6,0)+IF(BG18="S",-F$6-0.00001,0)) | G18: =IF(BH18="","",IF(BH18="x",G$6,0)+IF(BH18="S",-G$6-0.00001,0)) | H18: =IF(BI18="","",IF(BI18="x",H$6,0)+IF(BI18="S",-H$6-0.00001,0)) -> 2 | I18: =IF(BJ18="","",IF(BJ18="x",I$6,0)+IF(BJ18="S",-I$6-0.00001,0)) | J18: =IF(BK18="","",IF(BK18="x",J$6,0)+IF(BK18="S",-J$6-0.00001,0)) | K18: =IF(BL18="","",IF(BL18="x",K$6,0)+IF(BL18="S",-K$6-0.00001,0)) | L18: =IF(BM18="","",IF(BM18="x",L$6,0)+IF(BM18="S",-L$6-0.00001,0)) | M18: =IF(BN18="","",IF(BN18="x",M$6,0)+IF(BN18="S",-M$6-0.00001,0)) | ... BA18: =IF(DB18="","",IF(DB18="x",BA$6,0)+IF(DB18="S",-BA$6-0.00001,0)) | BB18: No | BG18: =IF(NOT(ISERROR(HLOOKUP(Standings!BG$3,Entries!$C52:$K52,1,FALSE))),"x",IF(NOT(ISERROR(HLOOKUP(Standings!BG$3,Entries!$L52:$L52,1,FALSE))),"S","")) | BH18: =IF(NOT(ISERROR(HLOOKUP(Standings!BH$3,Entries!$C52:$K52,1,FALSE))),"x",IF(NOT(ISERROR(HLOOKUP(Standings!BH$3,Entries!$L52:$L52,1,FALSE))),"S","")) | BI18: =IF(NOT(ISERROR(HLOOKUP(Standings!BI$3,Entries!$C52:$K52,1,FALSE))),"x",IF(NOT(ISERROR(HLOOKUP(Standings!BI$3,Entries!$L52:$L52,1,FALSE))),"S","")) -> x | BJ18: =IF(NOT(ISERROR(HLOOKUP(Standings!BJ$3,Entries!$C52:$K52,1,FALSE))),"x",IF(NOT(ISERROR(HLOOKUP(Standings!BJ$3,Entries!$L52:$L52,1,FALSE))),"S","")) | BK18: =IF(NOT(ISERROR(HLOOKUP(Standings!BK$3,Entries!$C52:$K52,1,FALSE))),"x",IF(NOT(ISERROR(HLOOKUP(Standings!BK$3,Entries!$L52:$L52,1,FALSE))),"S","")) | BL18: =IF(NOT(ISERROR(HLOOKUP(Standings!BL$3,Entries!$C52:$K52,1,FALSE))),"x",IF(NOT(ISERROR(HLOOKUP(Standings!BL$3,Entries!$L52:$L52,1,FALSE))),"S","")) | BM18: =IF(NOT(ISERROR(HLOOKUP(Standings!BM$3,Entries!$C52:$K52,1,FALSE))),"x",IF(NOT(ISERROR(HLOOKUP(Standings!BM$3,Entries!$L52:$L52,1,FALSE))),"S","")) | BN18: =IF(NOT(ISERROR(HLOOKUP(Standings!BN$3,Entries!$C52:$K52,1,FALSE))),"x",IF(NOT(ISERROR(HLOOKUP(Standings!BN$3,Entries!$L52:$L52,1,FALSE))),"S","")) | ... DB18: =IF(NOT(ISERROR(HLOOKUP(Standings!DB$3,Entries!$C52:$K52,1,FALSE))),"x",IF(NOT(ISERROR(HLOOKUP(Standings!DB$3,Entries!$L52:$L52,1,FALSE))),"S",""))
